2024-05-28 20:04:24,883	[ERROR]	/home/app_admin/venv_travelog/lib64/python3.9/site-packages/django/core/handlers/exception.py(Line:125)	Invalid HTTP_HOST header: '34.230.218.223'. You may need to add '34.230.218.223' to ALLOWED_HOSTS.
Traceback (most recent call last):
  File "/home/app_admin/venv_travelog/lib64/python3.9/site-packages/django/core/handlers/exception.py", line 56, in inner
    response = get_response(request)
  File "/home/app_admin/venv_travelog/lib64/python3.9/site-packages/django/utils/deprecation.py", line 135, in __call__
    response = self.process_request(request)
  File "/home/app_admin/venv_travelog/lib64/python3.9/site-packages/django/middleware/common.py", line 48, in process_request
    host = request.get_host()
  File "/home/app_admin/venv_travelog/lib64/python3.9/site-packages/django/http/request.py", line 152, in get_host
    raise DisallowedHost(msg)
django.core.exceptions.DisallowedHost: Invalid HTTP_HOST header: '34.230.218.223'. You may need to add '34.230.218.223' to ALLOWED_HOSTS.
2024-05-28 20:04:24,896	[WARNING]	/home/app_admin/venv_travelog/lib64/python3.9/site-packages/django/utils/log.py(Line:241)	Bad Request: /
2024-05-28 20:07:27,299	[ERROR]	/home/app_admin/venv_travelog/lib64/python3.9/site-packages/django/core/handlers/exception.py(Line:125)	Invalid HTTP_HOST header: '34.230.218.223'. You may need to add '34.230.218.223' to ALLOWED_HOSTS.
Traceback (most recent call last):
  File "/home/app_admin/venv_travelog/lib64/python3.9/site-packages/django/core/handlers/exception.py", line 56, in inner
    response = get_response(request)
  File "/home/app_admin/venv_travelog/lib64/python3.9/site-packages/django/utils/deprecation.py", line 135, in __call__
    response = self.process_request(request)
  File "/home/app_admin/venv_travelog/lib64/python3.9/site-packages/django/middleware/common.py", line 48, in process_request
    host = request.get_host()
  File "/home/app_admin/venv_travelog/lib64/python3.9/site-packages/django/http/request.py", line 152, in get_host
    raise DisallowedHost(msg)
django.core.exceptions.DisallowedHost: Invalid HTTP_HOST header: '34.230.218.223'. You may need to add '34.230.218.223' to ALLOWED_HOSTS.
2024-05-28 20:07:27,299	[WARNING]	/home/app_admin/venv_travelog/lib64/python3.9/site-packages/django/utils/log.py(Line:241)	Bad Request: //
2024-05-28 20:30:06,291	[ERROR]	/home/app_admin/venv_travelog/lib64/python3.9/site-packages/django/core/handlers/exception.py(Line:125)	Invalid HTTP_HOST header: '34.230.218.223'. You may need to add '34.230.218.223' to ALLOWED_HOSTS.
Traceback (most recent call last):
  File "/home/app_admin/venv_travelog/lib64/python3.9/site-packages/django/core/handlers/exception.py", line 56, in inner
    response = get_response(request)
  File "/home/app_admin/venv_travelog/lib64/python3.9/site-packages/django/utils/deprecation.py", line 135, in __call__
    response = self.process_request(request)
  File "/home/app_admin/venv_travelog/lib64/python3.9/site-packages/django/middleware/common.py", line 48, in process_request
    host = request.get_host()
  File "/home/app_admin/venv_travelog/lib64/python3.9/site-packages/django/http/request.py", line 152, in get_host
    raise DisallowedHost(msg)
django.core.exceptions.DisallowedHost: Invalid HTTP_HOST header: '34.230.218.223'. You may need to add '34.230.218.223' to ALLOWED_HOSTS.
2024-05-28 20:30:06,291	[WARNING]	/home/app_admin/venv_travelog/lib64/python3.9/site-packages/django/utils/log.py(Line:241)	Bad Request: /
2024-05-28 20:55:41,817	[ERROR]	/home/app_admin/venv_travelog/lib64/python3.9/site-packages/django/core/handlers/exception.py(Line:125)	Invalid HTTP_HOST header: '34.230.218.223'. You may need to add '34.230.218.223' to ALLOWED_HOSTS.
Traceback (most recent call last):
  File "/home/app_admin/venv_travelog/lib64/python3.9/site-packages/django/core/handlers/exception.py", line 56, in inner
    response = get_response(request)
  File "/home/app_admin/venv_travelog/lib64/python3.9/site-packages/django/utils/deprecation.py", line 135, in __call__
    response = self.process_request(request)
  File "/home/app_admin/venv_travelog/lib64/python3.9/site-packages/django/middleware/common.py", line 48, in process_request
    host = request.get_host()
  File "/home/app_admin/venv_travelog/lib64/python3.9/site-packages/django/http/request.py", line 152, in get_host
    raise DisallowedHost(msg)
django.core.exceptions.DisallowedHost: Invalid HTTP_HOST header: '34.230.218.223'. You may need to add '34.230.218.223' to ALLOWED_HOSTS.
2024-05-28 20:55:41,818	[WARNING]	/home/app_admin/venv_travelog/lib64/python3.9/site-packages/django/utils/log.py(Line:241)	Bad Request: /owa/auth/logon.aspx
2024-05-28 21:23:16,815	[ERROR]	/home/app_admin/venv_travelog/lib64/python3.9/site-packages/django/core/handlers/exception.py(Line:125)	Invalid HTTP_HOST header: '34.230.218.223'. You may need to add '34.230.218.223' to ALLOWED_HOSTS.
Traceback (most recent call last):
  File "/home/app_admin/venv_travelog/lib64/python3.9/site-packages/django/core/handlers/exception.py", line 56, in inner
    response = get_response(request)
  File "/home/app_admin/venv_travelog/lib64/python3.9/site-packages/django/utils/deprecation.py", line 135, in __call__
    response = self.process_request(request)
  File "/home/app_admin/venv_travelog/lib64/python3.9/site-packages/django/middleware/common.py", line 48, in process_request
    host = request.get_host()
  File "/home/app_admin/venv_travelog/lib64/python3.9/site-packages/django/http/request.py", line 152, in get_host
    raise DisallowedHost(msg)
django.core.exceptions.DisallowedHost: Invalid HTTP_HOST header: '34.230.218.223'. You may need to add '34.230.218.223' to ALLOWED_HOSTS.
2024-05-28 21:23:16,816	[WARNING]	/home/app_admin/venv_travelog/lib64/python3.9/site-packages/django/utils/log.py(Line:241)	Bad Request: /cgi-bin/luci/;stok=/locale
2024-05-28 21:28:10,860	[ERROR]	/home/app_admin/venv_travelog/lib64/python3.9/site-packages/django/core/handlers/exception.py(Line:125)	Invalid HTTP_HOST header: '34.230.218.223'. You may need to add '34.230.218.223' to ALLOWED_HOSTS.
Traceback (most recent call last):
  File "/home/app_admin/venv_travelog/lib64/python3.9/site-packages/django/core/handlers/exception.py", line 56, in inner
    response = get_response(request)
  File "/home/app_admin/venv_travelog/lib64/python3.9/site-packages/django/utils/deprecation.py", line 135, in __call__
    response = self.process_request(request)
  File "/home/app_admin/venv_travelog/lib64/python3.9/site-packages/django/middleware/common.py", line 48, in process_request
    host = request.get_host()
  File "/home/app_admin/venv_travelog/lib64/python3.9/site-packages/django/http/request.py", line 152, in get_host
    raise DisallowedHost(msg)
django.core.exceptions.DisallowedHost: Invalid HTTP_HOST header: '34.230.218.223'. You may need to add '34.230.218.223' to ALLOWED_HOSTS.
2024-05-28 21:28:10,861	[WARNING]	/home/app_admin/venv_travelog/lib64/python3.9/site-packages/django/utils/log.py(Line:241)	Bad Request: /
2024-05-28 22:14:00,621	[ERROR]	/home/app_admin/venv_travelog/lib64/python3.9/site-packages/django/core/handlers/exception.py(Line:125)	Invalid HTTP_HOST header: '0.0.0.0'. You may need to add '0.0.0.0' to ALLOWED_HOSTS.
Traceback (most recent call last):
  File "/home/app_admin/venv_travelog/lib64/python3.9/site-packages/django/core/handlers/exception.py", line 56, in inner
    response = get_response(request)
  File "/home/app_admin/venv_travelog/lib64/python3.9/site-packages/django/utils/deprecation.py", line 135, in __call__
    response = self.process_request(request)
  File "/home/app_admin/venv_travelog/lib64/python3.9/site-packages/django/middleware/common.py", line 48, in process_request
    host = request.get_host()
  File "/home/app_admin/venv_travelog/lib64/python3.9/site-packages/django/http/request.py", line 152, in get_host
    raise DisallowedHost(msg)
django.core.exceptions.DisallowedHost: Invalid HTTP_HOST header: '0.0.0.0'. You may need to add '0.0.0.0' to ALLOWED_HOSTS.
2024-05-28 22:14:00,622	[WARNING]	/home/app_admin/venv_travelog/lib64/python3.9/site-packages/django/utils/log.py(Line:241)	Bad Request: /
2024-05-28 22:46:18,789	[ERROR]	/home/app_admin/venv_travelog/lib64/python3.9/site-packages/django/core/handlers/exception.py(Line:125)	Invalid HTTP_HOST header: '34.230.218.223'. You may need to add '34.230.218.223' to ALLOWED_HOSTS.
Traceback (most recent call last):
  File "/home/app_admin/venv_travelog/lib64/python3.9/site-packages/django/core/handlers/exception.py", line 56, in inner
    response = get_response(request)
  File "/home/app_admin/venv_travelog/lib64/python3.9/site-packages/django/utils/deprecation.py", line 135, in __call__
    response = self.process_request(request)
  File "/home/app_admin/venv_travelog/lib64/python3.9/site-packages/django/middleware/common.py", line 48, in process_request
    host = request.get_host()
  File "/home/app_admin/venv_travelog/lib64/python3.9/site-packages/django/http/request.py", line 152, in get_host
    raise DisallowedHost(msg)
django.core.exceptions.DisallowedHost: Invalid HTTP_HOST header: '34.230.218.223'. You may need to add '34.230.218.223' to ALLOWED_HOSTS.
2024-05-28 22:46:18,791	[WARNING]	/home/app_admin/venv_travelog/lib64/python3.9/site-packages/django/utils/log.py(Line:241)	Bad Request: /
2024-05-28 22:46:24,022	[ERROR]	/home/app_admin/venv_travelog/lib64/python3.9/site-packages/django/core/handlers/exception.py(Line:125)	Invalid HTTP_HOST header: '34.230.218.223'. You may need to add '34.230.218.223' to ALLOWED_HOSTS.
Traceback (most recent call last):
  File "/home/app_admin/venv_travelog/lib64/python3.9/site-packages/django/core/handlers/exception.py", line 56, in inner
    response = get_response(request)
  File "/home/app_admin/venv_travelog/lib64/python3.9/site-packages/django/utils/deprecation.py", line 135, in __call__
    response = self.process_request(request)
  File "/home/app_admin/venv_travelog/lib64/python3.9/site-packages/django/middleware/common.py", line 48, in process_request
    host = request.get_host()
  File "/home/app_admin/venv_travelog/lib64/python3.9/site-packages/django/http/request.py", line 152, in get_host
    raise DisallowedHost(msg)
django.core.exceptions.DisallowedHost: Invalid HTTP_HOST header: '34.230.218.223'. You may need to add '34.230.218.223' to ALLOWED_HOSTS.
2024-05-28 22:46:24,022	[WARNING]	/home/app_admin/venv_travelog/lib64/python3.9/site-packages/django/utils/log.py(Line:241)	Bad Request: /
2024-05-28 22:47:04,511	[ERROR]	/home/app_admin/venv_travelog/lib64/python3.9/site-packages/django/core/handlers/exception.py(Line:125)	Invalid HTTP_HOST header: '34.230.218.223'. You may need to add '34.230.218.223' to ALLOWED_HOSTS.
Traceback (most recent call last):
  File "/home/app_admin/venv_travelog/lib64/python3.9/site-packages/django/core/handlers/exception.py", line 56, in inner
    response = get_response(request)
  File "/home/app_admin/venv_travelog/lib64/python3.9/site-packages/django/utils/deprecation.py", line 135, in __call__
    response = self.process_request(request)
  File "/home/app_admin/venv_travelog/lib64/python3.9/site-packages/django/middleware/common.py", line 48, in process_request
    host = request.get_host()
  File "/home/app_admin/venv_travelog/lib64/python3.9/site-packages/django/http/request.py", line 152, in get_host
    raise DisallowedHost(msg)
django.core.exceptions.DisallowedHost: Invalid HTTP_HOST header: '34.230.218.223'. You may need to add '34.230.218.223' to ALLOWED_HOSTS.
2024-05-28 22:47:04,512	[WARNING]	/home/app_admin/venv_travelog/lib64/python3.9/site-packages/django/utils/log.py(Line:241)	Bad Request: /
2024-05-28 22:47:05,878	[ERROR]	/home/app_admin/venv_travelog/lib64/python3.9/site-packages/django/core/handlers/exception.py(Line:125)	Invalid HTTP_HOST header: '34.230.218.223'. You may need to add '34.230.218.223' to ALLOWED_HOSTS.
Traceback (most recent call last):
  File "/home/app_admin/venv_travelog/lib64/python3.9/site-packages/django/core/handlers/exception.py", line 56, in inner
    response = get_response(request)
  File "/home/app_admin/venv_travelog/lib64/python3.9/site-packages/django/utils/deprecation.py", line 135, in __call__
    response = self.process_request(request)
  File "/home/app_admin/venv_travelog/lib64/python3.9/site-packages/django/middleware/common.py", line 48, in process_request
    host = request.get_host()
  File "/home/app_admin/venv_travelog/lib64/python3.9/site-packages/django/http/request.py", line 152, in get_host
    raise DisallowedHost(msg)
django.core.exceptions.DisallowedHost: Invalid HTTP_HOST header: '34.230.218.223'. You may need to add '34.230.218.223' to ALLOWED_HOSTS.
2024-05-28 22:47:05,878	[WARNING]	/home/app_admin/venv_travelog/lib64/python3.9/site-packages/django/utils/log.py(Line:241)	Bad Request: /favicon.ico
2024-05-28 22:47:07,238	[ERROR]	/home/app_admin/venv_travelog/lib64/python3.9/site-packages/django/core/handlers/exception.py(Line:125)	Invalid HTTP_HOST header: '34.230.218.223'. You may need to add '34.230.218.223' to ALLOWED_HOSTS.
Traceback (most recent call last):
  File "/home/app_admin/venv_travelog/lib64/python3.9/site-packages/django/core/handlers/exception.py", line 56, in inner
    response = get_response(request)
  File "/home/app_admin/venv_travelog/lib64/python3.9/site-packages/django/utils/deprecation.py", line 135, in __call__
    response = self.process_request(request)
  File "/home/app_admin/venv_travelog/lib64/python3.9/site-packages/django/middleware/common.py", line 48, in process_request
    host = request.get_host()
  File "/home/app_admin/venv_travelog/lib64/python3.9/site-packages/django/http/request.py", line 152, in get_host
    raise DisallowedHost(msg)
django.core.exceptions.DisallowedHost: Invalid HTTP_HOST header: '34.230.218.223'. You may need to add '34.230.218.223' to ALLOWED_HOSTS.
2024-05-28 22:47:07,238	[WARNING]	/home/app_admin/venv_travelog/lib64/python3.9/site-packages/django/utils/log.py(Line:241)	Bad Request: /sitemap.xml
2024-05-28 22:47:07,280	[ERROR]	/home/app_admin/venv_travelog/lib64/python3.9/site-packages/django/core/handlers/exception.py(Line:125)	Invalid HTTP_HOST header: '34.230.218.223'. You may need to add '34.230.218.223' to ALLOWED_HOSTS.
Traceback (most recent call last):
  File "/home/app_admin/venv_travelog/lib64/python3.9/site-packages/django/core/handlers/exception.py", line 56, in inner
    response = get_response(request)
  File "/home/app_admin/venv_travelog/lib64/python3.9/site-packages/django/utils/deprecation.py", line 135, in __call__
    response = self.process_request(request)
  File "/home/app_admin/venv_travelog/lib64/python3.9/site-packages/django/middleware/common.py", line 48, in process_request
    host = request.get_host()
  File "/home/app_admin/venv_travelog/lib64/python3.9/site-packages/django/http/request.py", line 152, in get_host
    raise DisallowedHost(msg)
django.core.exceptions.DisallowedHost: Invalid HTTP_HOST header: '34.230.218.223'. You may need to add '34.230.218.223' to ALLOWED_HOSTS.
2024-05-28 22:47:07,281	[WARNING]	/home/app_admin/venv_travelog/lib64/python3.9/site-packages/django/utils/log.py(Line:241)	Bad Request: /robots.txt
2024-05-28 23:42:46,680	[ERROR]	/home/app_admin/venv_travelog/lib64/python3.9/site-packages/django/core/handlers/exception.py(Line:125)	Invalid HTTP_HOST header: '34.230.218.223:443'. You may need to add '34.230.218.223' to ALLOWED_HOSTS.
Traceback (most recent call last):
  File "/home/app_admin/venv_travelog/lib64/python3.9/site-packages/django/core/handlers/exception.py", line 56, in inner
    response = get_response(request)
  File "/home/app_admin/venv_travelog/lib64/python3.9/site-packages/django/utils/deprecation.py", line 135, in __call__
    response = self.process_request(request)
  File "/home/app_admin/venv_travelog/lib64/python3.9/site-packages/django/middleware/common.py", line 48, in process_request
    host = request.get_host()
  File "/home/app_admin/venv_travelog/lib64/python3.9/site-packages/django/http/request.py", line 152, in get_host
    raise DisallowedHost(msg)
django.core.exceptions.DisallowedHost: Invalid HTTP_HOST header: '34.230.218.223:443'. You may need to add '34.230.218.223' to ALLOWED_HOSTS.
2024-05-28 23:42:46,682	[WARNING]	/home/app_admin/venv_travelog/lib64/python3.9/site-packages/django/utils/log.py(Line:241)	Bad Request: /
2024-05-29 00:23:29,347	[ERROR]	/home/app_admin/venv_travelog/lib64/python3.9/site-packages/django/core/handlers/exception.py(Line:125)	Invalid HTTP_HOST header: '34.230.218.223'. You may need to add '34.230.218.223' to ALLOWED_HOSTS.
Traceback (most recent call last):
  File "/home/app_admin/venv_travelog/lib64/python3.9/site-packages/django/core/handlers/exception.py", line 56, in inner
    response = get_response(request)
  File "/home/app_admin/venv_travelog/lib64/python3.9/site-packages/django/utils/deprecation.py", line 135, in __call__
    response = self.process_request(request)
  File "/home/app_admin/venv_travelog/lib64/python3.9/site-packages/django/middleware/common.py", line 48, in process_request
    host = request.get_host()
  File "/home/app_admin/venv_travelog/lib64/python3.9/site-packages/django/http/request.py", line 152, in get_host
    raise DisallowedHost(msg)
django.core.exceptions.DisallowedHost: Invalid HTTP_HOST header: '34.230.218.223'. You may need to add '34.230.218.223' to ALLOWED_HOSTS.
2024-05-29 00:23:29,347	[WARNING]	/home/app_admin/venv_travelog/lib64/python3.9/site-packages/django/utils/log.py(Line:241)	Bad Request: /.env
2024-05-29 01:12:15,346	[ERROR]	/home/app_admin/venv_travelog/lib64/python3.9/site-packages/django/core/handlers/exception.py(Line:125)	Invalid HTTP_HOST header: '34.230.218.223:443'. You may need to add '34.230.218.223' to ALLOWED_HOSTS.
Traceback (most recent call last):
  File "/home/app_admin/venv_travelog/lib64/python3.9/site-packages/django/core/handlers/exception.py", line 56, in inner
    response = get_response(request)
  File "/home/app_admin/venv_travelog/lib64/python3.9/site-packages/django/utils/deprecation.py", line 135, in __call__
    response = self.process_request(request)
  File "/home/app_admin/venv_travelog/lib64/python3.9/site-packages/django/middleware/common.py", line 48, in process_request
    host = request.get_host()
  File "/home/app_admin/venv_travelog/lib64/python3.9/site-packages/django/http/request.py", line 152, in get_host
    raise DisallowedHost(msg)
django.core.exceptions.DisallowedHost: Invalid HTTP_HOST header: '34.230.218.223:443'. You may need to add '34.230.218.223' to ALLOWED_HOSTS.
2024-05-29 01:12:15,346	[WARNING]	/home/app_admin/venv_travelog/lib64/python3.9/site-packages/django/utils/log.py(Line:241)	Bad Request: /
2024-05-29 01:21:11,293	[ERROR]	/home/app_admin/venv_travelog/lib64/python3.9/site-packages/django/core/handlers/exception.py(Line:125)	Invalid HTTP_HOST header: '34.230.218.223:443'. You may need to add '34.230.218.223' to ALLOWED_HOSTS.
Traceback (most recent call last):
  File "/home/app_admin/venv_travelog/lib64/python3.9/site-packages/django/core/handlers/exception.py", line 56, in inner
    response = get_response(request)
  File "/home/app_admin/venv_travelog/lib64/python3.9/site-packages/django/utils/deprecation.py", line 135, in __call__
    response = self.process_request(request)
  File "/home/app_admin/venv_travelog/lib64/python3.9/site-packages/django/middleware/common.py", line 48, in process_request
    host = request.get_host()
  File "/home/app_admin/venv_travelog/lib64/python3.9/site-packages/django/http/request.py", line 152, in get_host
    raise DisallowedHost(msg)
django.core.exceptions.DisallowedHost: Invalid HTTP_HOST header: '34.230.218.223:443'. You may need to add '34.230.218.223' to ALLOWED_HOSTS.
2024-05-29 01:21:11,294	[WARNING]	/home/app_admin/venv_travelog/lib64/python3.9/site-packages/django/utils/log.py(Line:241)	Bad Request: /Autodiscover/Autodiscover.xml
2024-05-29 01:33:56,455	[ERROR]	/home/app_admin/venv_travelog/lib64/python3.9/site-packages/django/core/handlers/exception.py(Line:125)	Invalid HTTP_HOST header: '34.230.218.223:443'. You may need to add '34.230.218.223' to ALLOWED_HOSTS.
Traceback (most recent call last):
  File "/home/app_admin/venv_travelog/lib64/python3.9/site-packages/django/core/handlers/exception.py", line 56, in inner
    response = get_response(request)
  File "/home/app_admin/venv_travelog/lib64/python3.9/site-packages/django/utils/deprecation.py", line 135, in __call__
    response = self.process_request(request)
  File "/home/app_admin/venv_travelog/lib64/python3.9/site-packages/django/middleware/common.py", line 48, in process_request
    host = request.get_host()
  File "/home/app_admin/venv_travelog/lib64/python3.9/site-packages/django/http/request.py", line 152, in get_host
    raise DisallowedHost(msg)
django.core.exceptions.DisallowedHost: Invalid HTTP_HOST header: '34.230.218.223:443'. You may need to add '34.230.218.223' to ALLOWED_HOSTS.
2024-05-29 01:33:56,456	[WARNING]	/home/app_admin/venv_travelog/lib64/python3.9/site-packages/django/utils/log.py(Line:241)	Bad Request: /vendor/phpunit/phpunit/src/Util/PHP/eval-stdin.php
2024-05-29 01:36:23,485	[ERROR]	/home/app_admin/venv_travelog/lib64/python3.9/site-packages/django/core/handlers/exception.py(Line:125)	Invalid HTTP_HOST header: '34.230.218.223'. You may need to add '34.230.218.223' to ALLOWED_HOSTS.
Traceback (most recent call last):
  File "/home/app_admin/venv_travelog/lib64/python3.9/site-packages/django/core/handlers/exception.py", line 56, in inner
    response = get_response(request)
  File "/home/app_admin/venv_travelog/lib64/python3.9/site-packages/django/utils/deprecation.py", line 135, in __call__
    response = self.process_request(request)
  File "/home/app_admin/venv_travelog/lib64/python3.9/site-packages/django/middleware/common.py", line 48, in process_request
    host = request.get_host()
  File "/home/app_admin/venv_travelog/lib64/python3.9/site-packages/django/http/request.py", line 152, in get_host
    raise DisallowedHost(msg)
django.core.exceptions.DisallowedHost: Invalid HTTP_HOST header: '34.230.218.223'. You may need to add '34.230.218.223' to ALLOWED_HOSTS.
2024-05-29 01:36:23,486	[WARNING]	/home/app_admin/venv_travelog/lib64/python3.9/site-packages/django/utils/log.py(Line:241)	Bad Request: /
2024-05-29 01:36:24,223	[ERROR]	/home/app_admin/venv_travelog/lib64/python3.9/site-packages/django/core/handlers/exception.py(Line:125)	Invalid HTTP_HOST header: '34.230.218.223'. You may need to add '34.230.218.223' to ALLOWED_HOSTS.
Traceback (most recent call last):
  File "/home/app_admin/venv_travelog/lib64/python3.9/site-packages/django/core/handlers/exception.py", line 56, in inner
    response = get_response(request)
  File "/home/app_admin/venv_travelog/lib64/python3.9/site-packages/django/utils/deprecation.py", line 135, in __call__
    response = self.process_request(request)
  File "/home/app_admin/venv_travelog/lib64/python3.9/site-packages/django/middleware/common.py", line 48, in process_request
    host = request.get_host()
  File "/home/app_admin/venv_travelog/lib64/python3.9/site-packages/django/http/request.py", line 152, in get_host
    raise DisallowedHost(msg)
django.core.exceptions.DisallowedHost: Invalid HTTP_HOST header: '34.230.218.223'. You may need to add '34.230.218.223' to ALLOWED_HOSTS.
2024-05-29 01:36:24,223	[WARNING]	/home/app_admin/venv_travelog/lib64/python3.9/site-packages/django/utils/log.py(Line:241)	Bad Request: /favicon.ico
2024-05-29 01:39:58,765	[ERROR]	/home/app_admin/venv_travelog/lib64/python3.9/site-packages/django/core/handlers/exception.py(Line:125)	Invalid HTTP_HOST header: '34.230.218.223:443'. You may need to add '34.230.218.223' to ALLOWED_HOSTS.
Traceback (most recent call last):
  File "/home/app_admin/venv_travelog/lib64/python3.9/site-packages/django/core/handlers/exception.py", line 56, in inner
    response = get_response(request)
  File "/home/app_admin/venv_travelog/lib64/python3.9/site-packages/django/utils/deprecation.py", line 135, in __call__
    response = self.process_request(request)
  File "/home/app_admin/venv_travelog/lib64/python3.9/site-packages/django/middleware/common.py", line 48, in process_request
    host = request.get_host()
  File "/home/app_admin/venv_travelog/lib64/python3.9/site-packages/django/http/request.py", line 152, in get_host
    raise DisallowedHost(msg)
django.core.exceptions.DisallowedHost: Invalid HTTP_HOST header: '34.230.218.223:443'. You may need to add '34.230.218.223' to ALLOWED_HOSTS.
2024-05-29 01:39:58,766	[WARNING]	/home/app_admin/venv_travelog/lib64/python3.9/site-packages/django/utils/log.py(Line:241)	Bad Request: /vendor/phpunit/phpunit/src/Util/PHP/eval-stdin.php
2024-05-29 02:00:02,908	[ERROR]	/home/app_admin/venv_travelog/lib64/python3.9/site-packages/django/core/handlers/exception.py(Line:125)	Invalid HTTP_HOST header: '34.230.218.223:443'. You may need to add '34.230.218.223' to ALLOWED_HOSTS.
Traceback (most recent call last):
  File "/home/app_admin/venv_travelog/lib64/python3.9/site-packages/django/core/handlers/exception.py", line 56, in inner
    response = get_response(request)
  File "/home/app_admin/venv_travelog/lib64/python3.9/site-packages/django/utils/deprecation.py", line 135, in __call__
    response = self.process_request(request)
  File "/home/app_admin/venv_travelog/lib64/python3.9/site-packages/django/middleware/common.py", line 48, in process_request
    host = request.get_host()
  File "/home/app_admin/venv_travelog/lib64/python3.9/site-packages/django/http/request.py", line 152, in get_host
    raise DisallowedHost(msg)
django.core.exceptions.DisallowedHost: Invalid HTTP_HOST header: '34.230.218.223:443'. You may need to add '34.230.218.223' to ALLOWED_HOSTS.
2024-05-29 02:00:02,925	[WARNING]	/home/app_admin/venv_travelog/lib64/python3.9/site-packages/django/utils/log.py(Line:241)	Bad Request: /
2024-05-29 02:16:28,308	[WARNING]	/home/app_admin/venv_travelog/lib64/python3.9/site-packages/django/utils/log.py(Line:241)	Not Found: /favicon.ico
2024-05-29 02:16:28,968	[WARNING]	/home/app_admin/venv_travelog/lib64/python3.9/site-packages/django/utils/log.py(Line:241)	Not Found: /favicon.ico
2024-05-29 02:16:30,366	[WARNING]	/home/app_admin/venv_travelog/lib64/python3.9/site-packages/django/utils/log.py(Line:241)	Not Found: /favicon.ico
2024-05-29 02:22:36,224	[ERROR]	/home/app_admin/venv_travelog/lib64/python3.9/site-packages/django/core/handlers/exception.py(Line:125)	Invalid HTTP_HOST header: '34.230.218.223'. You may need to add '34.230.218.223' to ALLOWED_HOSTS.
Traceback (most recent call last):
  File "/home/app_admin/venv_travelog/lib64/python3.9/site-packages/django/core/handlers/exception.py", line 56, in inner
    response = get_response(request)
  File "/home/app_admin/venv_travelog/lib64/python3.9/site-packages/django/utils/deprecation.py", line 135, in __call__
    response = self.process_request(request)
  File "/home/app_admin/venv_travelog/lib64/python3.9/site-packages/django/middleware/common.py", line 48, in process_request
    host = request.get_host()
  File "/home/app_admin/venv_travelog/lib64/python3.9/site-packages/django/http/request.py", line 152, in get_host
    raise DisallowedHost(msg)
django.core.exceptions.DisallowedHost: Invalid HTTP_HOST header: '34.230.218.223'. You may need to add '34.230.218.223' to ALLOWED_HOSTS.
2024-05-29 02:22:36,225	[WARNING]	/home/app_admin/venv_travelog/lib64/python3.9/site-packages/django/utils/log.py(Line:241)	Bad Request: /
2024-05-29 02:38:59,129	[ERROR]	/home/app_admin/venv_travelog/lib64/python3.9/site-packages/django/core/handlers/exception.py(Line:125)	Invalid HTTP_HOST header: '34.230.218.223'. You may need to add '34.230.218.223' to ALLOWED_HOSTS.
Traceback (most recent call last):
  File "/home/app_admin/venv_travelog/lib64/python3.9/site-packages/django/core/handlers/exception.py", line 56, in inner
    response = get_response(request)
  File "/home/app_admin/venv_travelog/lib64/python3.9/site-packages/django/utils/deprecation.py", line 135, in __call__
    response = self.process_request(request)
  File "/home/app_admin/venv_travelog/lib64/python3.9/site-packages/django/middleware/common.py", line 48, in process_request
    host = request.get_host()
  File "/home/app_admin/venv_travelog/lib64/python3.9/site-packages/django/http/request.py", line 152, in get_host
    raise DisallowedHost(msg)
django.core.exceptions.DisallowedHost: Invalid HTTP_HOST header: '34.230.218.223'. You may need to add '34.230.218.223' to ALLOWED_HOSTS.
2024-05-29 02:38:59,129	[WARNING]	/home/app_admin/venv_travelog/lib64/python3.9/site-packages/django/utils/log.py(Line:241)	Bad Request: /
2024-05-29 02:48:07,446	[ERROR]	/home/app_admin/venv_travelog/lib64/python3.9/site-packages/django/core/handlers/exception.py(Line:125)	Invalid HTTP_HOST header: '34.230.218.223'. You may need to add '34.230.218.223' to ALLOWED_HOSTS.
Traceback (most recent call last):
  File "/home/app_admin/venv_travelog/lib64/python3.9/site-packages/django/core/handlers/exception.py", line 56, in inner
    response = get_response(request)
  File "/home/app_admin/venv_travelog/lib64/python3.9/site-packages/django/utils/deprecation.py", line 135, in __call__
    response = self.process_request(request)
  File "/home/app_admin/venv_travelog/lib64/python3.9/site-packages/django/middleware/common.py", line 48, in process_request
    host = request.get_host()
  File "/home/app_admin/venv_travelog/lib64/python3.9/site-packages/django/http/request.py", line 152, in get_host
    raise DisallowedHost(msg)
django.core.exceptions.DisallowedHost: Invalid HTTP_HOST header: '34.230.218.223'. You may need to add '34.230.218.223' to ALLOWED_HOSTS.
2024-05-29 02:48:07,447	[WARNING]	/home/app_admin/venv_travelog/lib64/python3.9/site-packages/django/utils/log.py(Line:241)	Bad Request: /
2024-05-29 02:48:08,160	[ERROR]	/home/app_admin/venv_travelog/lib64/python3.9/site-packages/django/core/handlers/exception.py(Line:125)	Invalid HTTP_HOST header: '34.230.218.223'. You may need to add '34.230.218.223' to ALLOWED_HOSTS.
Traceback (most recent call last):
  File "/home/app_admin/venv_travelog/lib64/python3.9/site-packages/django/core/handlers/exception.py", line 56, in inner
    response = get_response(request)
  File "/home/app_admin/venv_travelog/lib64/python3.9/site-packages/django/utils/deprecation.py", line 135, in __call__
    response = self.process_request(request)
  File "/home/app_admin/venv_travelog/lib64/python3.9/site-packages/django/middleware/common.py", line 48, in process_request
    host = request.get_host()
  File "/home/app_admin/venv_travelog/lib64/python3.9/site-packages/django/http/request.py", line 152, in get_host
    raise DisallowedHost(msg)
django.core.exceptions.DisallowedHost: Invalid HTTP_HOST header: '34.230.218.223'. You may need to add '34.230.218.223' to ALLOWED_HOSTS.
2024-05-29 02:48:08,160	[WARNING]	/home/app_admin/venv_travelog/lib64/python3.9/site-packages/django/utils/log.py(Line:241)	Bad Request: /favicon.ico
2024-05-29 03:02:28,566	[ERROR]	/home/app_admin/venv_travelog/lib64/python3.9/site-packages/django/core/handlers/exception.py(Line:125)	Invalid HTTP_HOST header: '34.230.218.223:443'. You may need to add '34.230.218.223' to ALLOWED_HOSTS.
Traceback (most recent call last):
  File "/home/app_admin/venv_travelog/lib64/python3.9/site-packages/django/core/handlers/exception.py", line 56, in inner
    response = get_response(request)
  File "/home/app_admin/venv_travelog/lib64/python3.9/site-packages/django/utils/deprecation.py", line 135, in __call__
    response = self.process_request(request)
  File "/home/app_admin/venv_travelog/lib64/python3.9/site-packages/django/middleware/common.py", line 48, in process_request
    host = request.get_host()
  File "/home/app_admin/venv_travelog/lib64/python3.9/site-packages/django/http/request.py", line 152, in get_host
    raise DisallowedHost(msg)
django.core.exceptions.DisallowedHost: Invalid HTTP_HOST header: '34.230.218.223:443'. You may need to add '34.230.218.223' to ALLOWED_HOSTS.
2024-05-29 03:02:28,566	[WARNING]	/home/app_admin/venv_travelog/lib64/python3.9/site-packages/django/utils/log.py(Line:241)	Bad Request: /console/
2024-05-29 03:05:10,344	[ERROR]	/home/app_admin/venv_travelog/lib64/python3.9/site-packages/django/core/handlers/exception.py(Line:125)	Invalid HTTP_HOST header: '34.230.218.223'. You may need to add '34.230.218.223' to ALLOWED_HOSTS.
Traceback (most recent call last):
  File "/home/app_admin/venv_travelog/lib64/python3.9/site-packages/django/core/handlers/exception.py", line 56, in inner
    response = get_response(request)
  File "/home/app_admin/venv_travelog/lib64/python3.9/site-packages/django/utils/deprecation.py", line 135, in __call__
    response = self.process_request(request)
  File "/home/app_admin/venv_travelog/lib64/python3.9/site-packages/django/middleware/common.py", line 48, in process_request
    host = request.get_host()
  File "/home/app_admin/venv_travelog/lib64/python3.9/site-packages/django/http/request.py", line 152, in get_host
    raise DisallowedHost(msg)
django.core.exceptions.DisallowedHost: Invalid HTTP_HOST header: '34.230.218.223'. You may need to add '34.230.218.223' to ALLOWED_HOSTS.
2024-05-29 03:05:10,345	[WARNING]	/home/app_admin/venv_travelog/lib64/python3.9/site-packages/django/utils/log.py(Line:241)	Bad Request: /
2024-05-29 03:11:29,167	[ERROR]	/home/app_admin/venv_travelog/lib64/python3.9/site-packages/django/core/handlers/exception.py(Line:125)	Invalid HTTP_HOST header: '34.230.218.223:443'. You may need to add '34.230.218.223' to ALLOWED_HOSTS.
Traceback (most recent call last):
  File "/home/app_admin/venv_travelog/lib64/python3.9/site-packages/django/core/handlers/exception.py", line 56, in inner
    response = get_response(request)
  File "/home/app_admin/venv_travelog/lib64/python3.9/site-packages/django/utils/deprecation.py", line 135, in __call__
    response = self.process_request(request)
  File "/home/app_admin/venv_travelog/lib64/python3.9/site-packages/django/middleware/common.py", line 48, in process_request
    host = request.get_host()
  File "/home/app_admin/venv_travelog/lib64/python3.9/site-packages/django/http/request.py", line 152, in get_host
    raise DisallowedHost(msg)
django.core.exceptions.DisallowedHost: Invalid HTTP_HOST header: '34.230.218.223:443'. You may need to add '34.230.218.223' to ALLOWED_HOSTS.
2024-05-29 03:11:29,167	[WARNING]	/home/app_admin/venv_travelog/lib64/python3.9/site-packages/django/utils/log.py(Line:241)	Bad Request: /_ignition/execute-solution
2024-05-29 03:22:47,520	[ERROR]	/home/app_admin/venv_travelog/lib64/python3.9/site-packages/django/core/handlers/exception.py(Line:125)	Invalid HTTP_HOST header: '34.230.218.223:443'. You may need to add '34.230.218.223' to ALLOWED_HOSTS.
Traceback (most recent call last):
  File "/home/app_admin/venv_travelog/lib64/python3.9/site-packages/django/core/handlers/exception.py", line 56, in inner
    response = get_response(request)
  File "/home/app_admin/venv_travelog/lib64/python3.9/site-packages/django/utils/deprecation.py", line 135, in __call__
    response = self.process_request(request)
  File "/home/app_admin/venv_travelog/lib64/python3.9/site-packages/django/middleware/common.py", line 48, in process_request
    host = request.get_host()
  File "/home/app_admin/venv_travelog/lib64/python3.9/site-packages/django/http/request.py", line 152, in get_host
    raise DisallowedHost(msg)
django.core.exceptions.DisallowedHost: Invalid HTTP_HOST header: '34.230.218.223:443'. You may need to add '34.230.218.223' to ALLOWED_HOSTS.
2024-05-29 03:22:47,521	[WARNING]	/home/app_admin/venv_travelog/lib64/python3.9/site-packages/django/utils/log.py(Line:241)	Bad Request: /
2024-05-29 03:32:44,605	[ERROR]	/home/app_admin/venv_travelog/lib64/python3.9/site-packages/django/core/handlers/exception.py(Line:125)	Invalid HTTP_HOST header: '34.230.218.223'. You may need to add '34.230.218.223' to ALLOWED_HOSTS.
Traceback (most recent call last):
  File "/home/app_admin/venv_travelog/lib64/python3.9/site-packages/django/core/handlers/exception.py", line 56, in inner
    response = get_response(request)
  File "/home/app_admin/venv_travelog/lib64/python3.9/site-packages/django/utils/deprecation.py", line 135, in __call__
    response = self.process_request(request)
  File "/home/app_admin/venv_travelog/lib64/python3.9/site-packages/django/middleware/common.py", line 48, in process_request
    host = request.get_host()
  File "/home/app_admin/venv_travelog/lib64/python3.9/site-packages/django/http/request.py", line 152, in get_host
    raise DisallowedHost(msg)
django.core.exceptions.DisallowedHost: Invalid HTTP_HOST header: '34.230.218.223'. You may need to add '34.230.218.223' to ALLOWED_HOSTS.
2024-05-29 03:32:44,605	[WARNING]	/home/app_admin/venv_travelog/lib64/python3.9/site-packages/django/utils/log.py(Line:241)	Bad Request: /
2024-05-29 03:38:24,370	[ERROR]	/home/app_admin/venv_travelog/lib64/python3.9/site-packages/django/core/handlers/exception.py(Line:125)	Invalid HTTP_HOST header: '34.230.218.223:443'. You may need to add '34.230.218.223' to ALLOWED_HOSTS.
Traceback (most recent call last):
  File "/home/app_admin/venv_travelog/lib64/python3.9/site-packages/django/core/handlers/exception.py", line 56, in inner
    response = get_response(request)
  File "/home/app_admin/venv_travelog/lib64/python3.9/site-packages/django/utils/deprecation.py", line 135, in __call__
    response = self.process_request(request)
  File "/home/app_admin/venv_travelog/lib64/python3.9/site-packages/django/middleware/common.py", line 48, in process_request
    host = request.get_host()
  File "/home/app_admin/venv_travelog/lib64/python3.9/site-packages/django/http/request.py", line 152, in get_host
    raise DisallowedHost(msg)
django.core.exceptions.DisallowedHost: Invalid HTTP_HOST header: '34.230.218.223:443'. You may need to add '34.230.218.223' to ALLOWED_HOSTS.
2024-05-29 03:38:24,371	[WARNING]	/home/app_admin/venv_travelog/lib64/python3.9/site-packages/django/utils/log.py(Line:241)	Bad Request: /
2024-05-29 04:27:42,562	[ERROR]	/home/app_admin/venv_travelog/lib64/python3.9/site-packages/django/core/handlers/exception.py(Line:125)	Invalid HTTP_HOST header: '34.230.218.223:443'. You may need to add '34.230.218.223' to ALLOWED_HOSTS.
Traceback (most recent call last):
  File "/home/app_admin/venv_travelog/lib64/python3.9/site-packages/django/core/handlers/exception.py", line 56, in inner
    response = get_response(request)
  File "/home/app_admin/venv_travelog/lib64/python3.9/site-packages/django/utils/deprecation.py", line 135, in __call__
    response = self.process_request(request)
  File "/home/app_admin/venv_travelog/lib64/python3.9/site-packages/django/middleware/common.py", line 48, in process_request
    host = request.get_host()
  File "/home/app_admin/venv_travelog/lib64/python3.9/site-packages/django/http/request.py", line 152, in get_host
    raise DisallowedHost(msg)
django.core.exceptions.DisallowedHost: Invalid HTTP_HOST header: '34.230.218.223:443'. You may need to add '34.230.218.223' to ALLOWED_HOSTS.
2024-05-29 04:27:42,562	[WARNING]	/home/app_admin/venv_travelog/lib64/python3.9/site-packages/django/utils/log.py(Line:241)	Bad Request: /actuator/gateway/routes
2024-05-29 04:56:03,954	[ERROR]	/home/app_admin/venv_travelog/lib64/python3.9/site-packages/django/core/handlers/exception.py(Line:125)	Invalid HTTP_HOST header: '34.230.218.223:443'. You may need to add '34.230.218.223' to ALLOWED_HOSTS.
Traceback (most recent call last):
  File "/home/app_admin/venv_travelog/lib64/python3.9/site-packages/django/core/handlers/exception.py", line 56, in inner
    response = get_response(request)
  File "/home/app_admin/venv_travelog/lib64/python3.9/site-packages/django/utils/deprecation.py", line 135, in __call__
    response = self.process_request(request)
  File "/home/app_admin/venv_travelog/lib64/python3.9/site-packages/django/middleware/common.py", line 48, in process_request
    host = request.get_host()
  File "/home/app_admin/venv_travelog/lib64/python3.9/site-packages/django/http/request.py", line 152, in get_host
    raise DisallowedHost(msg)
django.core.exceptions.DisallowedHost: Invalid HTTP_HOST header: '34.230.218.223:443'. You may need to add '34.230.218.223' to ALLOWED_HOSTS.
2024-05-29 04:56:03,955	[WARNING]	/home/app_admin/venv_travelog/lib64/python3.9/site-packages/django/utils/log.py(Line:241)	Bad Request: /geoserver
2024-05-29 05:06:14,396	[ERROR]	/home/app_admin/venv_travelog/lib64/python3.9/site-packages/django/core/handlers/exception.py(Line:125)	Invalid HTTP_HOST header: '34.230.218.223:443'. You may need to add '34.230.218.223' to ALLOWED_HOSTS.
Traceback (most recent call last):
  File "/home/app_admin/venv_travelog/lib64/python3.9/site-packages/django/core/handlers/exception.py", line 56, in inner
    response = get_response(request)
  File "/home/app_admin/venv_travelog/lib64/python3.9/site-packages/django/utils/deprecation.py", line 135, in __call__
    response = self.process_request(request)
  File "/home/app_admin/venv_travelog/lib64/python3.9/site-packages/django/middleware/common.py", line 48, in process_request
    host = request.get_host()
  File "/home/app_admin/venv_travelog/lib64/python3.9/site-packages/django/http/request.py", line 152, in get_host
    raise DisallowedHost(msg)
django.core.exceptions.DisallowedHost: Invalid HTTP_HOST header: '34.230.218.223:443'. You may need to add '34.230.218.223' to ALLOWED_HOSTS.
2024-05-29 05:06:14,396	[WARNING]	/home/app_admin/venv_travelog/lib64/python3.9/site-packages/django/utils/log.py(Line:241)	Bad Request: /
2024-05-29 07:21:56,211	[ERROR]	/home/app_admin/venv_travelog/lib64/python3.9/site-packages/django/core/handlers/exception.py(Line:125)	Invalid HTTP_HOST header: '34.230.218.223'. You may need to add '34.230.218.223' to ALLOWED_HOSTS.
Traceback (most recent call last):
  File "/home/app_admin/venv_travelog/lib64/python3.9/site-packages/django/core/handlers/exception.py", line 56, in inner
    response = get_response(request)
  File "/home/app_admin/venv_travelog/lib64/python3.9/site-packages/django/utils/deprecation.py", line 135, in __call__
    response = self.process_request(request)
  File "/home/app_admin/venv_travelog/lib64/python3.9/site-packages/django/middleware/common.py", line 48, in process_request
    host = request.get_host()
  File "/home/app_admin/venv_travelog/lib64/python3.9/site-packages/django/http/request.py", line 152, in get_host
    raise DisallowedHost(msg)
django.core.exceptions.DisallowedHost: Invalid HTTP_HOST header: '34.230.218.223'. You may need to add '34.230.218.223' to ALLOWED_HOSTS.
2024-05-29 07:21:56,212	[WARNING]	/home/app_admin/venv_travelog/lib64/python3.9/site-packages/django/utils/log.py(Line:241)	Bad Request: /cgi-bin/luci/;stok=/locale
2024-05-29 08:25:33,490	[ERROR]	/home/app_admin/venv_travelog/lib64/python3.9/site-packages/django/core/handlers/exception.py(Line:125)	Invalid HTTP_HOST header: '34.230.218.223'. You may need to add '34.230.218.223' to ALLOWED_HOSTS.
Traceback (most recent call last):
  File "/home/app_admin/venv_travelog/lib64/python3.9/site-packages/django/core/handlers/exception.py", line 56, in inner
    response = get_response(request)
  File "/home/app_admin/venv_travelog/lib64/python3.9/site-packages/django/utils/deprecation.py", line 135, in __call__
    response = self.process_request(request)
  File "/home/app_admin/venv_travelog/lib64/python3.9/site-packages/django/middleware/common.py", line 48, in process_request
    host = request.get_host()
  File "/home/app_admin/venv_travelog/lib64/python3.9/site-packages/django/http/request.py", line 152, in get_host
    raise DisallowedHost(msg)
django.core.exceptions.DisallowedHost: Invalid HTTP_HOST header: '34.230.218.223'. You may need to add '34.230.218.223' to ALLOWED_HOSTS.
2024-05-29 08:25:33,490	[WARNING]	/home/app_admin/venv_travelog/lib64/python3.9/site-packages/django/utils/log.py(Line:241)	Bad Request: /
2024-05-29 08:44:05,721	[ERROR]	/home/app_admin/venv_travelog/lib64/python3.9/site-packages/django/core/handlers/exception.py(Line:125)	Invalid HTTP_HOST header: '34.230.218.223'. You may need to add '34.230.218.223' to ALLOWED_HOSTS.
Traceback (most recent call last):
  File "/home/app_admin/venv_travelog/lib64/python3.9/site-packages/django/core/handlers/exception.py", line 56, in inner
    response = get_response(request)
  File "/home/app_admin/venv_travelog/lib64/python3.9/site-packages/django/utils/deprecation.py", line 135, in __call__
    response = self.process_request(request)
  File "/home/app_admin/venv_travelog/lib64/python3.9/site-packages/django/middleware/common.py", line 48, in process_request
    host = request.get_host()
  File "/home/app_admin/venv_travelog/lib64/python3.9/site-packages/django/http/request.py", line 152, in get_host
    raise DisallowedHost(msg)
django.core.exceptions.DisallowedHost: Invalid HTTP_HOST header: '34.230.218.223'. You may need to add '34.230.218.223' to ALLOWED_HOSTS.
2024-05-29 08:44:05,721	[WARNING]	/home/app_admin/venv_travelog/lib64/python3.9/site-packages/django/utils/log.py(Line:241)	Bad Request: /
2024-05-29 09:44:02,498	[ERROR]	/home/app_admin/venv_travelog/lib64/python3.9/site-packages/django/core/handlers/exception.py(Line:125)	Invalid HTTP_HOST header: '34.230.218.223'. You may need to add '34.230.218.223' to ALLOWED_HOSTS.
Traceback (most recent call last):
  File "/home/app_admin/venv_travelog/lib64/python3.9/site-packages/django/core/handlers/exception.py", line 56, in inner
    response = get_response(request)
  File "/home/app_admin/venv_travelog/lib64/python3.9/site-packages/django/utils/deprecation.py", line 135, in __call__
    response = self.process_request(request)
  File "/home/app_admin/venv_travelog/lib64/python3.9/site-packages/django/middleware/common.py", line 48, in process_request
    host = request.get_host()
  File "/home/app_admin/venv_travelog/lib64/python3.9/site-packages/django/http/request.py", line 152, in get_host
    raise DisallowedHost(msg)
django.core.exceptions.DisallowedHost: Invalid HTTP_HOST header: '34.230.218.223'. You may need to add '34.230.218.223' to ALLOWED_HOSTS.
2024-05-29 09:44:02,498	[WARNING]	/home/app_admin/venv_travelog/lib64/python3.9/site-packages/django/utils/log.py(Line:241)	Bad Request: /
2024-05-29 10:30:42,241	[ERROR]	/home/app_admin/venv_travelog/lib64/python3.9/site-packages/django/core/handlers/exception.py(Line:125)	Invalid HTTP_HOST header: '34.230.218.223'. You may need to add '34.230.218.223' to ALLOWED_HOSTS.
Traceback (most recent call last):
  File "/home/app_admin/venv_travelog/lib64/python3.9/site-packages/django/core/handlers/exception.py", line 56, in inner
    response = get_response(request)
  File "/home/app_admin/venv_travelog/lib64/python3.9/site-packages/django/utils/deprecation.py", line 135, in __call__
    response = self.process_request(request)
  File "/home/app_admin/venv_travelog/lib64/python3.9/site-packages/django/middleware/common.py", line 48, in process_request
    host = request.get_host()
  File "/home/app_admin/venv_travelog/lib64/python3.9/site-packages/django/http/request.py", line 152, in get_host
    raise DisallowedHost(msg)
django.core.exceptions.DisallowedHost: Invalid HTTP_HOST header: '34.230.218.223'. You may need to add '34.230.218.223' to ALLOWED_HOSTS.
2024-05-29 10:30:42,242	[WARNING]	/home/app_admin/venv_travelog/lib64/python3.9/site-packages/django/utils/log.py(Line:241)	Bad Request: /
2024-05-29 11:08:52,604	[ERROR]	/home/app_admin/venv_travelog/lib64/python3.9/site-packages/django/core/handlers/exception.py(Line:125)	Invalid HTTP_HOST header: '34.230.218.223'. You may need to add '34.230.218.223' to ALLOWED_HOSTS.
Traceback (most recent call last):
  File "/home/app_admin/venv_travelog/lib64/python3.9/site-packages/django/core/handlers/exception.py", line 56, in inner
    response = get_response(request)
  File "/home/app_admin/venv_travelog/lib64/python3.9/site-packages/django/utils/deprecation.py", line 135, in __call__
    response = self.process_request(request)
  File "/home/app_admin/venv_travelog/lib64/python3.9/site-packages/django/middleware/common.py", line 48, in process_request
    host = request.get_host()
  File "/home/app_admin/venv_travelog/lib64/python3.9/site-packages/django/http/request.py", line 152, in get_host
    raise DisallowedHost(msg)
django.core.exceptions.DisallowedHost: Invalid HTTP_HOST header: '34.230.218.223'. You may need to add '34.230.218.223' to ALLOWED_HOSTS.
2024-05-29 11:08:52,605	[WARNING]	/home/app_admin/venv_travelog/lib64/python3.9/site-packages/django/utils/log.py(Line:241)	Bad Request: /dns-query
2024-05-29 11:08:53,006	[ERROR]	/home/app_admin/venv_travelog/lib64/python3.9/site-packages/django/core/handlers/exception.py(Line:125)	Invalid HTTP_HOST header: '34.230.218.223'. You may need to add '34.230.218.223' to ALLOWED_HOSTS.
Traceback (most recent call last):
  File "/home/app_admin/venv_travelog/lib64/python3.9/site-packages/django/core/handlers/exception.py", line 56, in inner
    response = get_response(request)
  File "/home/app_admin/venv_travelog/lib64/python3.9/site-packages/django/utils/deprecation.py", line 135, in __call__
    response = self.process_request(request)
  File "/home/app_admin/venv_travelog/lib64/python3.9/site-packages/django/middleware/common.py", line 48, in process_request
    host = request.get_host()
  File "/home/app_admin/venv_travelog/lib64/python3.9/site-packages/django/http/request.py", line 152, in get_host
    raise DisallowedHost(msg)
django.core.exceptions.DisallowedHost: Invalid HTTP_HOST header: '34.230.218.223'. You may need to add '34.230.218.223' to ALLOWED_HOSTS.
2024-05-29 11:08:53,007	[WARNING]	/home/app_admin/venv_travelog/lib64/python3.9/site-packages/django/utils/log.py(Line:241)	Bad Request: /dns-query
2024-05-29 11:08:53,181	[ERROR]	/home/app_admin/venv_travelog/lib64/python3.9/site-packages/django/core/handlers/exception.py(Line:125)	Invalid HTTP_HOST header: '34.230.218.223'. You may need to add '34.230.218.223' to ALLOWED_HOSTS.
Traceback (most recent call last):
  File "/home/app_admin/venv_travelog/lib64/python3.9/site-packages/django/core/handlers/exception.py", line 56, in inner
    response = get_response(request)
  File "/home/app_admin/venv_travelog/lib64/python3.9/site-packages/django/utils/deprecation.py", line 135, in __call__
    response = self.process_request(request)
  File "/home/app_admin/venv_travelog/lib64/python3.9/site-packages/django/middleware/common.py", line 48, in process_request
    host = request.get_host()
  File "/home/app_admin/venv_travelog/lib64/python3.9/site-packages/django/http/request.py", line 152, in get_host
    raise DisallowedHost(msg)
django.core.exceptions.DisallowedHost: Invalid HTTP_HOST header: '34.230.218.223'. You may need to add '34.230.218.223' to ALLOWED_HOSTS.
2024-05-29 11:08:53,182	[WARNING]	/home/app_admin/venv_travelog/lib64/python3.9/site-packages/django/utils/log.py(Line:241)	Bad Request: /dns-query
2024-05-29 11:08:53,357	[ERROR]	/home/app_admin/venv_travelog/lib64/python3.9/site-packages/django/core/handlers/exception.py(Line:125)	Invalid HTTP_HOST header: '34.230.218.223'. You may need to add '34.230.218.223' to ALLOWED_HOSTS.
Traceback (most recent call last):
  File "/home/app_admin/venv_travelog/lib64/python3.9/site-packages/django/core/handlers/exception.py", line 56, in inner
    response = get_response(request)
  File "/home/app_admin/venv_travelog/lib64/python3.9/site-packages/django/utils/deprecation.py", line 135, in __call__
    response = self.process_request(request)
  File "/home/app_admin/venv_travelog/lib64/python3.9/site-packages/django/middleware/common.py", line 48, in process_request
    host = request.get_host()
  File "/home/app_admin/venv_travelog/lib64/python3.9/site-packages/django/http/request.py", line 152, in get_host
    raise DisallowedHost(msg)
django.core.exceptions.DisallowedHost: Invalid HTTP_HOST header: '34.230.218.223'. You may need to add '34.230.218.223' to ALLOWED_HOSTS.
2024-05-29 11:08:53,357	[WARNING]	/home/app_admin/venv_travelog/lib64/python3.9/site-packages/django/utils/log.py(Line:241)	Bad Request: /dns-query
2024-05-29 11:08:53,532	[ERROR]	/home/app_admin/venv_travelog/lib64/python3.9/site-packages/django/core/handlers/exception.py(Line:125)	Invalid HTTP_HOST header: '34.230.218.223'. You may need to add '34.230.218.223' to ALLOWED_HOSTS.
Traceback (most recent call last):
  File "/home/app_admin/venv_travelog/lib64/python3.9/site-packages/django/core/handlers/exception.py", line 56, in inner
    response = get_response(request)
  File "/home/app_admin/venv_travelog/lib64/python3.9/site-packages/django/utils/deprecation.py", line 135, in __call__
    response = self.process_request(request)
  File "/home/app_admin/venv_travelog/lib64/python3.9/site-packages/django/middleware/common.py", line 48, in process_request
    host = request.get_host()
  File "/home/app_admin/venv_travelog/lib64/python3.9/site-packages/django/http/request.py", line 152, in get_host
    raise DisallowedHost(msg)
django.core.exceptions.DisallowedHost: Invalid HTTP_HOST header: '34.230.218.223'. You may need to add '34.230.218.223' to ALLOWED_HOSTS.
2024-05-29 11:08:53,533	[WARNING]	/home/app_admin/venv_travelog/lib64/python3.9/site-packages/django/utils/log.py(Line:241)	Bad Request: /dns-query
2024-05-29 11:08:53,708	[ERROR]	/home/app_admin/venv_travelog/lib64/python3.9/site-packages/django/core/handlers/exception.py(Line:125)	Invalid HTTP_HOST header: '34.230.218.223'. You may need to add '34.230.218.223' to ALLOWED_HOSTS.
Traceback (most recent call last):
  File "/home/app_admin/venv_travelog/lib64/python3.9/site-packages/django/core/handlers/exception.py", line 56, in inner
    response = get_response(request)
  File "/home/app_admin/venv_travelog/lib64/python3.9/site-packages/django/utils/deprecation.py", line 135, in __call__
    response = self.process_request(request)
  File "/home/app_admin/venv_travelog/lib64/python3.9/site-packages/django/middleware/common.py", line 48, in process_request
    host = request.get_host()
  File "/home/app_admin/venv_travelog/lib64/python3.9/site-packages/django/http/request.py", line 152, in get_host
    raise DisallowedHost(msg)
django.core.exceptions.DisallowedHost: Invalid HTTP_HOST header: '34.230.218.223'. You may need to add '34.230.218.223' to ALLOWED_HOSTS.
2024-05-29 11:08:53,708	[WARNING]	/home/app_admin/venv_travelog/lib64/python3.9/site-packages/django/utils/log.py(Line:241)	Bad Request: /dns-query
2024-05-29 11:08:53,883	[ERROR]	/home/app_admin/venv_travelog/lib64/python3.9/site-packages/django/core/handlers/exception.py(Line:125)	Invalid HTTP_HOST header: '34.230.218.223'. You may need to add '34.230.218.223' to ALLOWED_HOSTS.
Traceback (most recent call last):
  File "/home/app_admin/venv_travelog/lib64/python3.9/site-packages/django/core/handlers/exception.py", line 56, in inner
    response = get_response(request)
  File "/home/app_admin/venv_travelog/lib64/python3.9/site-packages/django/utils/deprecation.py", line 135, in __call__
    response = self.process_request(request)
  File "/home/app_admin/venv_travelog/lib64/python3.9/site-packages/django/middleware/common.py", line 48, in process_request
    host = request.get_host()
  File "/home/app_admin/venv_travelog/lib64/python3.9/site-packages/django/http/request.py", line 152, in get_host
    raise DisallowedHost(msg)
django.core.exceptions.DisallowedHost: Invalid HTTP_HOST header: '34.230.218.223'. You may need to add '34.230.218.223' to ALLOWED_HOSTS.
2024-05-29 11:08:53,883	[WARNING]	/home/app_admin/venv_travelog/lib64/python3.9/site-packages/django/utils/log.py(Line:241)	Bad Request: /query
2024-05-29 11:08:54,058	[ERROR]	/home/app_admin/venv_travelog/lib64/python3.9/site-packages/django/core/handlers/exception.py(Line:125)	Invalid HTTP_HOST header: '34.230.218.223'. You may need to add '34.230.218.223' to ALLOWED_HOSTS.
Traceback (most recent call last):
  File "/home/app_admin/venv_travelog/lib64/python3.9/site-packages/django/core/handlers/exception.py", line 56, in inner
    response = get_response(request)
  File "/home/app_admin/venv_travelog/lib64/python3.9/site-packages/django/utils/deprecation.py", line 135, in __call__
    response = self.process_request(request)
  File "/home/app_admin/venv_travelog/lib64/python3.9/site-packages/django/middleware/common.py", line 48, in process_request
    host = request.get_host()
  File "/home/app_admin/venv_travelog/lib64/python3.9/site-packages/django/http/request.py", line 152, in get_host
    raise DisallowedHost(msg)
django.core.exceptions.DisallowedHost: Invalid HTTP_HOST header: '34.230.218.223'. You may need to add '34.230.218.223' to ALLOWED_HOSTS.
2024-05-29 11:08:54,059	[WARNING]	/home/app_admin/venv_travelog/lib64/python3.9/site-packages/django/utils/log.py(Line:241)	Bad Request: /query
2024-05-29 11:08:54,233	[ERROR]	/home/app_admin/venv_travelog/lib64/python3.9/site-packages/django/core/handlers/exception.py(Line:125)	Invalid HTTP_HOST header: '34.230.218.223'. You may need to add '34.230.218.223' to ALLOWED_HOSTS.
Traceback (most recent call last):
  File "/home/app_admin/venv_travelog/lib64/python3.9/site-packages/django/core/handlers/exception.py", line 56, in inner
    response = get_response(request)
  File "/home/app_admin/venv_travelog/lib64/python3.9/site-packages/django/utils/deprecation.py", line 135, in __call__
    response = self.process_request(request)
  File "/home/app_admin/venv_travelog/lib64/python3.9/site-packages/django/middleware/common.py", line 48, in process_request
    host = request.get_host()
  File "/home/app_admin/venv_travelog/lib64/python3.9/site-packages/django/http/request.py", line 152, in get_host
    raise DisallowedHost(msg)
django.core.exceptions.DisallowedHost: Invalid HTTP_HOST header: '34.230.218.223'. You may need to add '34.230.218.223' to ALLOWED_HOSTS.
2024-05-29 11:08:54,234	[WARNING]	/home/app_admin/venv_travelog/lib64/python3.9/site-packages/django/utils/log.py(Line:241)	Bad Request: /query
2024-05-29 11:08:54,410	[ERROR]	/home/app_admin/venv_travelog/lib64/python3.9/site-packages/django/core/handlers/exception.py(Line:125)	Invalid HTTP_HOST header: '34.230.218.223'. You may need to add '34.230.218.223' to ALLOWED_HOSTS.
Traceback (most recent call last):
  File "/home/app_admin/venv_travelog/lib64/python3.9/site-packages/django/core/handlers/exception.py", line 56, in inner
    response = get_response(request)
  File "/home/app_admin/venv_travelog/lib64/python3.9/site-packages/django/utils/deprecation.py", line 135, in __call__
    response = self.process_request(request)
  File "/home/app_admin/venv_travelog/lib64/python3.9/site-packages/django/middleware/common.py", line 48, in process_request
    host = request.get_host()
  File "/home/app_admin/venv_travelog/lib64/python3.9/site-packages/django/http/request.py", line 152, in get_host
    raise DisallowedHost(msg)
django.core.exceptions.DisallowedHost: Invalid HTTP_HOST header: '34.230.218.223'. You may need to add '34.230.218.223' to ALLOWED_HOSTS.
2024-05-29 11:08:54,410	[WARNING]	/home/app_admin/venv_travelog/lib64/python3.9/site-packages/django/utils/log.py(Line:241)	Bad Request: /query
2024-05-29 11:08:54,585	[ERROR]	/home/app_admin/venv_travelog/lib64/python3.9/site-packages/django/core/handlers/exception.py(Line:125)	Invalid HTTP_HOST header: '34.230.218.223'. You may need to add '34.230.218.223' to ALLOWED_HOSTS.
Traceback (most recent call last):
  File "/home/app_admin/venv_travelog/lib64/python3.9/site-packages/django/core/handlers/exception.py", line 56, in inner
    response = get_response(request)
  File "/home/app_admin/venv_travelog/lib64/python3.9/site-packages/django/utils/deprecation.py", line 135, in __call__
    response = self.process_request(request)
  File "/home/app_admin/venv_travelog/lib64/python3.9/site-packages/django/middleware/common.py", line 48, in process_request
    host = request.get_host()
  File "/home/app_admin/venv_travelog/lib64/python3.9/site-packages/django/http/request.py", line 152, in get_host
    raise DisallowedHost(msg)
django.core.exceptions.DisallowedHost: Invalid HTTP_HOST header: '34.230.218.223'. You may need to add '34.230.218.223' to ALLOWED_HOSTS.
2024-05-29 11:08:54,585	[WARNING]	/home/app_admin/venv_travelog/lib64/python3.9/site-packages/django/utils/log.py(Line:241)	Bad Request: /query
2024-05-29 11:08:54,760	[ERROR]	/home/app_admin/venv_travelog/lib64/python3.9/site-packages/django/core/handlers/exception.py(Line:125)	Invalid HTTP_HOST header: '34.230.218.223'. You may need to add '34.230.218.223' to ALLOWED_HOSTS.
Traceback (most recent call last):
  File "/home/app_admin/venv_travelog/lib64/python3.9/site-packages/django/core/handlers/exception.py", line 56, in inner
    response = get_response(request)
  File "/home/app_admin/venv_travelog/lib64/python3.9/site-packages/django/utils/deprecation.py", line 135, in __call__
    response = self.process_request(request)
  File "/home/app_admin/venv_travelog/lib64/python3.9/site-packages/django/middleware/common.py", line 48, in process_request
    host = request.get_host()
  File "/home/app_admin/venv_travelog/lib64/python3.9/site-packages/django/http/request.py", line 152, in get_host
    raise DisallowedHost(msg)
django.core.exceptions.DisallowedHost: Invalid HTTP_HOST header: '34.230.218.223'. You may need to add '34.230.218.223' to ALLOWED_HOSTS.
2024-05-29 11:08:54,761	[WARNING]	/home/app_admin/venv_travelog/lib64/python3.9/site-packages/django/utils/log.py(Line:241)	Bad Request: /query
2024-05-29 11:08:54,936	[ERROR]	/home/app_admin/venv_travelog/lib64/python3.9/site-packages/django/core/handlers/exception.py(Line:125)	Invalid HTTP_HOST header: '34.230.218.223'. You may need to add '34.230.218.223' to ALLOWED_HOSTS.
Traceback (most recent call last):
  File "/home/app_admin/venv_travelog/lib64/python3.9/site-packages/django/core/handlers/exception.py", line 56, in inner
    response = get_response(request)
  File "/home/app_admin/venv_travelog/lib64/python3.9/site-packages/django/utils/deprecation.py", line 135, in __call__
    response = self.process_request(request)
  File "/home/app_admin/venv_travelog/lib64/python3.9/site-packages/django/middleware/common.py", line 48, in process_request
    host = request.get_host()
  File "/home/app_admin/venv_travelog/lib64/python3.9/site-packages/django/http/request.py", line 152, in get_host
    raise DisallowedHost(msg)
django.core.exceptions.DisallowedHost: Invalid HTTP_HOST header: '34.230.218.223'. You may need to add '34.230.218.223' to ALLOWED_HOSTS.
2024-05-29 11:08:54,936	[WARNING]	/home/app_admin/venv_travelog/lib64/python3.9/site-packages/django/utils/log.py(Line:241)	Bad Request: /resolve
2024-05-29 11:08:55,111	[ERROR]	/home/app_admin/venv_travelog/lib64/python3.9/site-packages/django/core/handlers/exception.py(Line:125)	Invalid HTTP_HOST header: '34.230.218.223'. You may need to add '34.230.218.223' to ALLOWED_HOSTS.
Traceback (most recent call last):
  File "/home/app_admin/venv_travelog/lib64/python3.9/site-packages/django/core/handlers/exception.py", line 56, in inner
    response = get_response(request)
  File "/home/app_admin/venv_travelog/lib64/python3.9/site-packages/django/utils/deprecation.py", line 135, in __call__
    response = self.process_request(request)
  File "/home/app_admin/venv_travelog/lib64/python3.9/site-packages/django/middleware/common.py", line 48, in process_request
    host = request.get_host()
  File "/home/app_admin/venv_travelog/lib64/python3.9/site-packages/django/http/request.py", line 152, in get_host
    raise DisallowedHost(msg)
django.core.exceptions.DisallowedHost: Invalid HTTP_HOST header: '34.230.218.223'. You may need to add '34.230.218.223' to ALLOWED_HOSTS.
2024-05-29 11:08:55,111	[WARNING]	/home/app_admin/venv_travelog/lib64/python3.9/site-packages/django/utils/log.py(Line:241)	Bad Request: /resolve
2024-05-29 11:08:55,286	[ERROR]	/home/app_admin/venv_travelog/lib64/python3.9/site-packages/django/core/handlers/exception.py(Line:125)	Invalid HTTP_HOST header: '34.230.218.223'. You may need to add '34.230.218.223' to ALLOWED_HOSTS.
Traceback (most recent call last):
  File "/home/app_admin/venv_travelog/lib64/python3.9/site-packages/django/core/handlers/exception.py", line 56, in inner
    response = get_response(request)
  File "/home/app_admin/venv_travelog/lib64/python3.9/site-packages/django/utils/deprecation.py", line 135, in __call__
    response = self.process_request(request)
  File "/home/app_admin/venv_travelog/lib64/python3.9/site-packages/django/middleware/common.py", line 48, in process_request
    host = request.get_host()
  File "/home/app_admin/venv_travelog/lib64/python3.9/site-packages/django/http/request.py", line 152, in get_host
    raise DisallowedHost(msg)
django.core.exceptions.DisallowedHost: Invalid HTTP_HOST header: '34.230.218.223'. You may need to add '34.230.218.223' to ALLOWED_HOSTS.
2024-05-29 11:08:55,286	[WARNING]	/home/app_admin/venv_travelog/lib64/python3.9/site-packages/django/utils/log.py(Line:241)	Bad Request: /resolve
2024-05-29 11:08:55,461	[ERROR]	/home/app_admin/venv_travelog/lib64/python3.9/site-packages/django/core/handlers/exception.py(Line:125)	Invalid HTTP_HOST header: '34.230.218.223'. You may need to add '34.230.218.223' to ALLOWED_HOSTS.
Traceback (most recent call last):
  File "/home/app_admin/venv_travelog/lib64/python3.9/site-packages/django/core/handlers/exception.py", line 56, in inner
    response = get_response(request)
  File "/home/app_admin/venv_travelog/lib64/python3.9/site-packages/django/utils/deprecation.py", line 135, in __call__
    response = self.process_request(request)
  File "/home/app_admin/venv_travelog/lib64/python3.9/site-packages/django/middleware/common.py", line 48, in process_request
    host = request.get_host()
  File "/home/app_admin/venv_travelog/lib64/python3.9/site-packages/django/http/request.py", line 152, in get_host
    raise DisallowedHost(msg)
django.core.exceptions.DisallowedHost: Invalid HTTP_HOST header: '34.230.218.223'. You may need to add '34.230.218.223' to ALLOWED_HOSTS.
2024-05-29 11:08:55,462	[WARNING]	/home/app_admin/venv_travelog/lib64/python3.9/site-packages/django/utils/log.py(Line:241)	Bad Request: /resolve
2024-05-29 11:08:55,636	[ERROR]	/home/app_admin/venv_travelog/lib64/python3.9/site-packages/django/core/handlers/exception.py(Line:125)	Invalid HTTP_HOST header: '34.230.218.223'. You may need to add '34.230.218.223' to ALLOWED_HOSTS.
Traceback (most recent call last):
  File "/home/app_admin/venv_travelog/lib64/python3.9/site-packages/django/core/handlers/exception.py", line 56, in inner
    response = get_response(request)
  File "/home/app_admin/venv_travelog/lib64/python3.9/site-packages/django/utils/deprecation.py", line 135, in __call__
    response = self.process_request(request)
  File "/home/app_admin/venv_travelog/lib64/python3.9/site-packages/django/middleware/common.py", line 48, in process_request
    host = request.get_host()
  File "/home/app_admin/venv_travelog/lib64/python3.9/site-packages/django/http/request.py", line 152, in get_host
    raise DisallowedHost(msg)
django.core.exceptions.DisallowedHost: Invalid HTTP_HOST header: '34.230.218.223'. You may need to add '34.230.218.223' to ALLOWED_HOSTS.
2024-05-29 11:08:55,637	[WARNING]	/home/app_admin/venv_travelog/lib64/python3.9/site-packages/django/utils/log.py(Line:241)	Bad Request: /resolve
2024-05-29 11:08:55,812	[ERROR]	/home/app_admin/venv_travelog/lib64/python3.9/site-packages/django/core/handlers/exception.py(Line:125)	Invalid HTTP_HOST header: '34.230.218.223'. You may need to add '34.230.218.223' to ALLOWED_HOSTS.
Traceback (most recent call last):
  File "/home/app_admin/venv_travelog/lib64/python3.9/site-packages/django/core/handlers/exception.py", line 56, in inner
    response = get_response(request)
  File "/home/app_admin/venv_travelog/lib64/python3.9/site-packages/django/utils/deprecation.py", line 135, in __call__
    response = self.process_request(request)
  File "/home/app_admin/venv_travelog/lib64/python3.9/site-packages/django/middleware/common.py", line 48, in process_request
    host = request.get_host()
  File "/home/app_admin/venv_travelog/lib64/python3.9/site-packages/django/http/request.py", line 152, in get_host
    raise DisallowedHost(msg)
django.core.exceptions.DisallowedHost: Invalid HTTP_HOST header: '34.230.218.223'. You may need to add '34.230.218.223' to ALLOWED_HOSTS.
2024-05-29 11:08:55,812	[WARNING]	/home/app_admin/venv_travelog/lib64/python3.9/site-packages/django/utils/log.py(Line:241)	Bad Request: /resolve
2024-05-29 11:08:55,987	[ERROR]	/home/app_admin/venv_travelog/lib64/python3.9/site-packages/django/core/handlers/exception.py(Line:125)	Invalid HTTP_HOST header: '34.230.218.223'. You may need to add '34.230.218.223' to ALLOWED_HOSTS.
Traceback (most recent call last):
  File "/home/app_admin/venv_travelog/lib64/python3.9/site-packages/django/core/handlers/exception.py", line 56, in inner
    response = get_response(request)
  File "/home/app_admin/venv_travelog/lib64/python3.9/site-packages/django/utils/deprecation.py", line 135, in __call__
    response = self.process_request(request)
  File "/home/app_admin/venv_travelog/lib64/python3.9/site-packages/django/middleware/common.py", line 48, in process_request
    host = request.get_host()
  File "/home/app_admin/venv_travelog/lib64/python3.9/site-packages/django/http/request.py", line 152, in get_host
    raise DisallowedHost(msg)
django.core.exceptions.DisallowedHost: Invalid HTTP_HOST header: '34.230.218.223'. You may need to add '34.230.218.223' to ALLOWED_HOSTS.
2024-05-29 11:08:55,987	[WARNING]	/home/app_admin/venv_travelog/lib64/python3.9/site-packages/django/utils/log.py(Line:241)	Bad Request: /
2024-05-29 11:08:56,162	[ERROR]	/home/app_admin/venv_travelog/lib64/python3.9/site-packages/django/core/handlers/exception.py(Line:125)	Invalid HTTP_HOST header: '34.230.218.223'. You may need to add '34.230.218.223' to ALLOWED_HOSTS.
Traceback (most recent call last):
  File "/home/app_admin/venv_travelog/lib64/python3.9/site-packages/django/core/handlers/exception.py", line 56, in inner
    response = get_response(request)
  File "/home/app_admin/venv_travelog/lib64/python3.9/site-packages/django/utils/deprecation.py", line 135, in __call__
    response = self.process_request(request)
  File "/home/app_admin/venv_travelog/lib64/python3.9/site-packages/django/middleware/common.py", line 48, in process_request
    host = request.get_host()
  File "/home/app_admin/venv_travelog/lib64/python3.9/site-packages/django/http/request.py", line 152, in get_host
    raise DisallowedHost(msg)
django.core.exceptions.DisallowedHost: Invalid HTTP_HOST header: '34.230.218.223'. You may need to add '34.230.218.223' to ALLOWED_HOSTS.
2024-05-29 11:08:56,163	[WARNING]	/home/app_admin/venv_travelog/lib64/python3.9/site-packages/django/utils/log.py(Line:241)	Bad Request: /
2024-05-29 11:08:56,338	[ERROR]	/home/app_admin/venv_travelog/lib64/python3.9/site-packages/django/core/handlers/exception.py(Line:125)	Invalid HTTP_HOST header: '34.230.218.223'. You may need to add '34.230.218.223' to ALLOWED_HOSTS.
Traceback (most recent call last):
  File "/home/app_admin/venv_travelog/lib64/python3.9/site-packages/django/core/handlers/exception.py", line 56, in inner
    response = get_response(request)
  File "/home/app_admin/venv_travelog/lib64/python3.9/site-packages/django/utils/deprecation.py", line 135, in __call__
    response = self.process_request(request)
  File "/home/app_admin/venv_travelog/lib64/python3.9/site-packages/django/middleware/common.py", line 48, in process_request
    host = request.get_host()
  File "/home/app_admin/venv_travelog/lib64/python3.9/site-packages/django/http/request.py", line 152, in get_host
    raise DisallowedHost(msg)
django.core.exceptions.DisallowedHost: Invalid HTTP_HOST header: '34.230.218.223'. You may need to add '34.230.218.223' to ALLOWED_HOSTS.
2024-05-29 11:08:56,338	[WARNING]	/home/app_admin/venv_travelog/lib64/python3.9/site-packages/django/utils/log.py(Line:241)	Bad Request: /
2024-05-29 11:08:56,513	[ERROR]	/home/app_admin/venv_travelog/lib64/python3.9/site-packages/django/core/handlers/exception.py(Line:125)	Invalid HTTP_HOST header: '34.230.218.223'. You may need to add '34.230.218.223' to ALLOWED_HOSTS.
Traceback (most recent call last):
  File "/home/app_admin/venv_travelog/lib64/python3.9/site-packages/django/core/handlers/exception.py", line 56, in inner
    response = get_response(request)
  File "/home/app_admin/venv_travelog/lib64/python3.9/site-packages/django/utils/deprecation.py", line 135, in __call__
    response = self.process_request(request)
  File "/home/app_admin/venv_travelog/lib64/python3.9/site-packages/django/middleware/common.py", line 48, in process_request
    host = request.get_host()
  File "/home/app_admin/venv_travelog/lib64/python3.9/site-packages/django/http/request.py", line 152, in get_host
    raise DisallowedHost(msg)
django.core.exceptions.DisallowedHost: Invalid HTTP_HOST header: '34.230.218.223'. You may need to add '34.230.218.223' to ALLOWED_HOSTS.
2024-05-29 11:08:56,514	[WARNING]	/home/app_admin/venv_travelog/lib64/python3.9/site-packages/django/utils/log.py(Line:241)	Bad Request: /
2024-05-29 11:08:56,689	[ERROR]	/home/app_admin/venv_travelog/lib64/python3.9/site-packages/django/core/handlers/exception.py(Line:125)	Invalid HTTP_HOST header: '34.230.218.223'. You may need to add '34.230.218.223' to ALLOWED_HOSTS.
Traceback (most recent call last):
  File "/home/app_admin/venv_travelog/lib64/python3.9/site-packages/django/core/handlers/exception.py", line 56, in inner
    response = get_response(request)
  File "/home/app_admin/venv_travelog/lib64/python3.9/site-packages/django/utils/deprecation.py", line 135, in __call__
    response = self.process_request(request)
  File "/home/app_admin/venv_travelog/lib64/python3.9/site-packages/django/middleware/common.py", line 48, in process_request
    host = request.get_host()
  File "/home/app_admin/venv_travelog/lib64/python3.9/site-packages/django/http/request.py", line 152, in get_host
    raise DisallowedHost(msg)
django.core.exceptions.DisallowedHost: Invalid HTTP_HOST header: '34.230.218.223'. You may need to add '34.230.218.223' to ALLOWED_HOSTS.
2024-05-29 11:08:56,689	[WARNING]	/home/app_admin/venv_travelog/lib64/python3.9/site-packages/django/utils/log.py(Line:241)	Bad Request: /
2024-05-29 11:08:56,864	[ERROR]	/home/app_admin/venv_travelog/lib64/python3.9/site-packages/django/core/handlers/exception.py(Line:125)	Invalid HTTP_HOST header: '34.230.218.223'. You may need to add '34.230.218.223' to ALLOWED_HOSTS.
Traceback (most recent call last):
  File "/home/app_admin/venv_travelog/lib64/python3.9/site-packages/django/core/handlers/exception.py", line 56, in inner
    response = get_response(request)
  File "/home/app_admin/venv_travelog/lib64/python3.9/site-packages/django/utils/deprecation.py", line 135, in __call__
    response = self.process_request(request)
  File "/home/app_admin/venv_travelog/lib64/python3.9/site-packages/django/middleware/common.py", line 48, in process_request
    host = request.get_host()
  File "/home/app_admin/venv_travelog/lib64/python3.9/site-packages/django/http/request.py", line 152, in get_host
    raise DisallowedHost(msg)
django.core.exceptions.DisallowedHost: Invalid HTTP_HOST header: '34.230.218.223'. You may need to add '34.230.218.223' to ALLOWED_HOSTS.
2024-05-29 11:08:56,864	[WARNING]	/home/app_admin/venv_travelog/lib64/python3.9/site-packages/django/utils/log.py(Line:241)	Bad Request: /
2024-05-29 11:13:16,740	[ERROR]	/home/app_admin/venv_travelog/lib64/python3.9/site-packages/django/core/handlers/exception.py(Line:125)	Invalid HTTP_HOST header: '34.230.218.223'. You may need to add '34.230.218.223' to ALLOWED_HOSTS.
Traceback (most recent call last):
  File "/home/app_admin/venv_travelog/lib64/python3.9/site-packages/django/core/handlers/exception.py", line 56, in inner
    response = get_response(request)
  File "/home/app_admin/venv_travelog/lib64/python3.9/site-packages/django/utils/deprecation.py", line 135, in __call__
    response = self.process_request(request)
  File "/home/app_admin/venv_travelog/lib64/python3.9/site-packages/django/middleware/common.py", line 48, in process_request
    host = request.get_host()
  File "/home/app_admin/venv_travelog/lib64/python3.9/site-packages/django/http/request.py", line 152, in get_host
    raise DisallowedHost(msg)
django.core.exceptions.DisallowedHost: Invalid HTTP_HOST header: '34.230.218.223'. You may need to add '34.230.218.223' to ALLOWED_HOSTS.
2024-05-29 11:13:16,741	[WARNING]	/home/app_admin/venv_travelog/lib64/python3.9/site-packages/django/utils/log.py(Line:241)	Bad Request: /.git/config
2024-05-29 11:29:48,272	[ERROR]	/home/app_admin/venv_travelog/lib64/python3.9/site-packages/django/core/handlers/exception.py(Line:125)	Invalid HTTP_HOST header: '34.230.218.223:443'. You may need to add '34.230.218.223' to ALLOWED_HOSTS.
Traceback (most recent call last):
  File "/home/app_admin/venv_travelog/lib64/python3.9/site-packages/django/core/handlers/exception.py", line 56, in inner
    response = get_response(request)
  File "/home/app_admin/venv_travelog/lib64/python3.9/site-packages/django/utils/deprecation.py", line 135, in __call__
    response = self.process_request(request)
  File "/home/app_admin/venv_travelog/lib64/python3.9/site-packages/django/middleware/common.py", line 48, in process_request
    host = request.get_host()
  File "/home/app_admin/venv_travelog/lib64/python3.9/site-packages/django/http/request.py", line 152, in get_host
    raise DisallowedHost(msg)
django.core.exceptions.DisallowedHost: Invalid HTTP_HOST header: '34.230.218.223:443'. You may need to add '34.230.218.223' to ALLOWED_HOSTS.
2024-05-29 11:29:48,272	[WARNING]	/home/app_admin/venv_travelog/lib64/python3.9/site-packages/django/utils/log.py(Line:241)	Bad Request: /
2024-05-29 11:36:04,480	[ERROR]	/home/app_admin/venv_travelog/lib64/python3.9/site-packages/django/core/handlers/exception.py(Line:125)	Invalid HTTP_HOST header: '34.230.218.223'. You may need to add '34.230.218.223' to ALLOWED_HOSTS.
Traceback (most recent call last):
  File "/home/app_admin/venv_travelog/lib64/python3.9/site-packages/django/core/handlers/exception.py", line 56, in inner
    response = get_response(request)
  File "/home/app_admin/venv_travelog/lib64/python3.9/site-packages/django/utils/deprecation.py", line 135, in __call__
    response = self.process_request(request)
  File "/home/app_admin/venv_travelog/lib64/python3.9/site-packages/django/middleware/common.py", line 48, in process_request
    host = request.get_host()
  File "/home/app_admin/venv_travelog/lib64/python3.9/site-packages/django/http/request.py", line 152, in get_host
    raise DisallowedHost(msg)
django.core.exceptions.DisallowedHost: Invalid HTTP_HOST header: '34.230.218.223'. You may need to add '34.230.218.223' to ALLOWED_HOSTS.
2024-05-29 11:36:04,480	[WARNING]	/home/app_admin/venv_travelog/lib64/python3.9/site-packages/django/utils/log.py(Line:241)	Bad Request: /ReportServer
2024-05-29 11:51:11,346	[ERROR]	/home/app_admin/venv_travelog/lib64/python3.9/site-packages/django/core/handlers/exception.py(Line:125)	Invalid HTTP_HOST header: '34.230.218.223'. You may need to add '34.230.218.223' to ALLOWED_HOSTS.
Traceback (most recent call last):
  File "/home/app_admin/venv_travelog/lib64/python3.9/site-packages/django/core/handlers/exception.py", line 56, in inner
    response = get_response(request)
  File "/home/app_admin/venv_travelog/lib64/python3.9/site-packages/django/utils/deprecation.py", line 135, in __call__
    response = self.process_request(request)
  File "/home/app_admin/venv_travelog/lib64/python3.9/site-packages/django/middleware/common.py", line 48, in process_request
    host = request.get_host()
  File "/home/app_admin/venv_travelog/lib64/python3.9/site-packages/django/http/request.py", line 152, in get_host
    raise DisallowedHost(msg)
django.core.exceptions.DisallowedHost: Invalid HTTP_HOST header: '34.230.218.223'. You may need to add '34.230.218.223' to ALLOWED_HOSTS.
2024-05-29 11:51:11,346	[WARNING]	/home/app_admin/venv_travelog/lib64/python3.9/site-packages/django/utils/log.py(Line:241)	Bad Request: /cgi-bin/luci/;stok=/locale
2024-05-29 13:06:43,202	[ERROR]	/home/app_admin/venv_travelog/lib64/python3.9/site-packages/django/core/handlers/exception.py(Line:125)	Invalid HTTP_HOST header: '34.230.218.223'. You may need to add '34.230.218.223' to ALLOWED_HOSTS.
Traceback (most recent call last):
  File "/home/app_admin/venv_travelog/lib64/python3.9/site-packages/django/core/handlers/exception.py", line 56, in inner
    response = get_response(request)
  File "/home/app_admin/venv_travelog/lib64/python3.9/site-packages/django/utils/deprecation.py", line 135, in __call__
    response = self.process_request(request)
  File "/home/app_admin/venv_travelog/lib64/python3.9/site-packages/django/middleware/common.py", line 48, in process_request
    host = request.get_host()
  File "/home/app_admin/venv_travelog/lib64/python3.9/site-packages/django/http/request.py", line 152, in get_host
    raise DisallowedHost(msg)
django.core.exceptions.DisallowedHost: Invalid HTTP_HOST header: '34.230.218.223'. You may need to add '34.230.218.223' to ALLOWED_HOSTS.
2024-05-29 13:06:43,202	[WARNING]	/home/app_admin/venv_travelog/lib64/python3.9/site-packages/django/utils/log.py(Line:241)	Bad Request: /
2024-05-29 13:39:22,347	[ERROR]	/home/app_admin/venv_travelog/lib64/python3.9/site-packages/django/core/handlers/exception.py(Line:125)	Invalid HTTP_HOST header: '34.230.218.223'. You may need to add '34.230.218.223' to ALLOWED_HOSTS.
Traceback (most recent call last):
  File "/home/app_admin/venv_travelog/lib64/python3.9/site-packages/django/core/handlers/exception.py", line 56, in inner
    response = get_response(request)
  File "/home/app_admin/venv_travelog/lib64/python3.9/site-packages/django/utils/deprecation.py", line 135, in __call__
    response = self.process_request(request)
  File "/home/app_admin/venv_travelog/lib64/python3.9/site-packages/django/middleware/common.py", line 48, in process_request
    host = request.get_host()
  File "/home/app_admin/venv_travelog/lib64/python3.9/site-packages/django/http/request.py", line 152, in get_host
    raise DisallowedHost(msg)
django.core.exceptions.DisallowedHost: Invalid HTTP_HOST header: '34.230.218.223'. You may need to add '34.230.218.223' to ALLOWED_HOSTS.
2024-05-29 13:39:22,348	[WARNING]	/home/app_admin/venv_travelog/lib64/python3.9/site-packages/django/utils/log.py(Line:241)	Bad Request: /
2024-05-29 13:47:14,753	[ERROR]	/home/app_admin/venv_travelog/lib64/python3.9/site-packages/django/core/handlers/exception.py(Line:125)	Invalid HTTP_HOST header: '34.230.218.223:443'. You may need to add '34.230.218.223' to ALLOWED_HOSTS.
Traceback (most recent call last):
  File "/home/app_admin/venv_travelog/lib64/python3.9/site-packages/django/core/handlers/exception.py", line 56, in inner
    response = get_response(request)
  File "/home/app_admin/venv_travelog/lib64/python3.9/site-packages/django/utils/deprecation.py", line 135, in __call__
    response = self.process_request(request)
  File "/home/app_admin/venv_travelog/lib64/python3.9/site-packages/django/middleware/common.py", line 48, in process_request
    host = request.get_host()
  File "/home/app_admin/venv_travelog/lib64/python3.9/site-packages/django/http/request.py", line 152, in get_host
    raise DisallowedHost(msg)
django.core.exceptions.DisallowedHost: Invalid HTTP_HOST header: '34.230.218.223:443'. You may need to add '34.230.218.223' to ALLOWED_HOSTS.
2024-05-29 13:47:14,754	[WARNING]	/home/app_admin/venv_travelog/lib64/python3.9/site-packages/django/utils/log.py(Line:241)	Bad Request: /
2024-05-29 13:47:23,803	[ERROR]	/home/app_admin/venv_travelog/lib64/python3.9/site-packages/django/core/handlers/exception.py(Line:125)	Invalid HTTP_HOST header: '34.230.218.223'. You may need to add '34.230.218.223' to ALLOWED_HOSTS.
Traceback (most recent call last):
  File "/home/app_admin/venv_travelog/lib64/python3.9/site-packages/django/core/handlers/exception.py", line 56, in inner
    response = get_response(request)
  File "/home/app_admin/venv_travelog/lib64/python3.9/site-packages/django/utils/deprecation.py", line 135, in __call__
    response = self.process_request(request)
  File "/home/app_admin/venv_travelog/lib64/python3.9/site-packages/django/middleware/common.py", line 48, in process_request
    host = request.get_host()
  File "/home/app_admin/venv_travelog/lib64/python3.9/site-packages/django/http/request.py", line 152, in get_host
    raise DisallowedHost(msg)
django.core.exceptions.DisallowedHost: Invalid HTTP_HOST header: '34.230.218.223'. You may need to add '34.230.218.223' to ALLOWED_HOSTS.
2024-05-29 13:47:23,804	[WARNING]	/home/app_admin/venv_travelog/lib64/python3.9/site-packages/django/utils/log.py(Line:241)	Bad Request: /
2024-05-29 13:53:46,709	[ERROR]	/home/app_admin/venv_travelog/lib64/python3.9/site-packages/django/core/handlers/exception.py(Line:125)	Invalid HTTP_HOST header: '34.230.218.223:443'. You may need to add '34.230.218.223' to ALLOWED_HOSTS.
Traceback (most recent call last):
  File "/home/app_admin/venv_travelog/lib64/python3.9/site-packages/django/core/handlers/exception.py", line 56, in inner
    response = get_response(request)
  File "/home/app_admin/venv_travelog/lib64/python3.9/site-packages/django/utils/deprecation.py", line 135, in __call__
    response = self.process_request(request)
  File "/home/app_admin/venv_travelog/lib64/python3.9/site-packages/django/middleware/common.py", line 48, in process_request
    host = request.get_host()
  File "/home/app_admin/venv_travelog/lib64/python3.9/site-packages/django/http/request.py", line 152, in get_host
    raise DisallowedHost(msg)
django.core.exceptions.DisallowedHost: Invalid HTTP_HOST header: '34.230.218.223:443'. You may need to add '34.230.218.223' to ALLOWED_HOSTS.
2024-05-29 13:53:46,710	[WARNING]	/home/app_admin/venv_travelog/lib64/python3.9/site-packages/django/utils/log.py(Line:241)	Bad Request: /
2024-05-29 14:23:13,121	[ERROR]	/home/app_admin/venv_travelog/lib64/python3.9/site-packages/django/utils/log.py(Line:241)	Internal Server Error: /profile_edit/15
Traceback (most recent call last):
  File "/home/app_admin/venv_travelog/lib64/python3.9/site-packages/django/core/handlers/exception.py", line 56, in inner
    response = get_response(request)
  File "/home/app_admin/venv_travelog/lib64/python3.9/site-packages/django/core/handlers/base.py", line 220, in _get_response
    response = response.render()
  File "/home/app_admin/venv_travelog/lib64/python3.9/site-packages/django/template/response.py", line 114, in render
    self.content = self.rendered_content
  File "/home/app_admin/venv_travelog/lib64/python3.9/site-packages/django/template/response.py", line 92, in rendered_content
    return template.render(context, self._request)
  File "/home/app_admin/venv_travelog/lib64/python3.9/site-packages/django/template/backends/django.py", line 61, in render
    return self.template.render(context)
  File "/home/app_admin/venv_travelog/lib64/python3.9/site-packages/django/template/base.py", line 175, in render
    return self._render(context)
  File "/home/app_admin/venv_travelog/lib64/python3.9/site-packages/django/template/base.py", line 167, in _render
    return self.nodelist.render(context)
  File "/home/app_admin/venv_travelog/lib64/python3.9/site-packages/django/template/base.py", line 1005, in render
    return SafeString("".join([node.render_annotated(context) for node in self]))
  File "/home/app_admin/venv_travelog/lib64/python3.9/site-packages/django/template/base.py", line 1005, in <listcomp>
    return SafeString("".join([node.render_annotated(context) for node in self]))
  File "/home/app_admin/venv_travelog/lib64/python3.9/site-packages/django/template/base.py", line 966, in render_annotated
    return self.render(context)
  File "/home/app_admin/venv_travelog/lib64/python3.9/site-packages/django/template/loader_tags.py", line 157, in render
    return compiled_parent._render(context)
  File "/home/app_admin/venv_travelog/lib64/python3.9/site-packages/django/template/base.py", line 167, in _render
    return self.nodelist.render(context)
  File "/home/app_admin/venv_travelog/lib64/python3.9/site-packages/django/template/base.py", line 1005, in render
    return SafeString("".join([node.render_annotated(context) for node in self]))
  File "/home/app_admin/venv_travelog/lib64/python3.9/site-packages/django/template/base.py", line 1005, in <listcomp>
    return SafeString("".join([node.render_annotated(context) for node in self]))
  File "/home/app_admin/venv_travelog/lib64/python3.9/site-packages/django/template/base.py", line 966, in render_annotated
    return self.render(context)
  File "/home/app_admin/venv_travelog/lib64/python3.9/site-packages/django/template/loader_tags.py", line 63, in render
    result = block.nodelist.render(context)
  File "/home/app_admin/venv_travelog/lib64/python3.9/site-packages/django/template/base.py", line 1005, in render
    return SafeString("".join([node.render_annotated(context) for node in self]))
  File "/home/app_admin/venv_travelog/lib64/python3.9/site-packages/django/template/base.py", line 1005, in <listcomp>
    return SafeString("".join([node.render_annotated(context) for node in self]))
  File "/home/app_admin/venv_travelog/lib64/python3.9/site-packages/django/template/base.py", line 966, in render_annotated
    return self.render(context)
  File "/home/app_admin/venv_travelog/lib64/python3.9/site-packages/django/template/defaulttags.py", line 471, in render
    url = reverse(view_name, args=args, kwargs=kwargs, current_app=current_app)
  File "/home/app_admin/venv_travelog/lib64/python3.9/site-packages/django/urls/base.py", line 88, in reverse
    return resolver._reverse_with_prefix(view, prefix, *args, **kwargs)
  File "/home/app_admin/venv_travelog/lib64/python3.9/site-packages/django/urls/resolvers.py", line 828, in _reverse_with_prefix
    raise NoReverseMatch(msg)
django.urls.exceptions.NoReverseMatch: Reverse for 'profile_edited' not found. 'profile_edited' is not a valid view function or pattern name.
2024-05-29 14:23:13,428	[WARNING]	/home/app_admin/venv_travelog/lib64/python3.9/site-packages/django/utils/log.py(Line:241)	Not Found: /favicon.ico
2024-05-29 15:41:04,142	[ERROR]	/home/app_admin/venv_travelog/lib64/python3.9/site-packages/django/core/handlers/exception.py(Line:125)	Invalid HTTP_HOST header: '34.230.218.223'. You may need to add '34.230.218.223' to ALLOWED_HOSTS.
Traceback (most recent call last):
  File "/home/app_admin/venv_travelog/lib64/python3.9/site-packages/django/core/handlers/exception.py", line 56, in inner
    response = get_response(request)
  File "/home/app_admin/venv_travelog/lib64/python3.9/site-packages/django/utils/deprecation.py", line 135, in __call__
    response = self.process_request(request)
  File "/home/app_admin/venv_travelog/lib64/python3.9/site-packages/django/middleware/common.py", line 48, in process_request
    host = request.get_host()
  File "/home/app_admin/venv_travelog/lib64/python3.9/site-packages/django/http/request.py", line 152, in get_host
    raise DisallowedHost(msg)
django.core.exceptions.DisallowedHost: Invalid HTTP_HOST header: '34.230.218.223'. You may need to add '34.230.218.223' to ALLOWED_HOSTS.
2024-05-29 15:41:04,143	[WARNING]	/home/app_admin/venv_travelog/lib64/python3.9/site-packages/django/utils/log.py(Line:241)	Bad Request: /
2024-05-29 16:20:43,959	[WARNING]	/home/app_admin/venv_travelog/lib64/python3.9/site-packages/django/utils/log.py(Line:241)	Forbidden (CSRF token from POST incorrect.): /accounts/login/
2024-05-29 16:20:44,208	[WARNING]	/home/app_admin/venv_travelog/lib64/python3.9/site-packages/django/utils/log.py(Line:241)	Not Found: /favicon.ico
2024-05-29 16:56:47,901	[ERROR]	/home/app_admin/venv_travelog/lib64/python3.9/site-packages/django/core/handlers/exception.py(Line:125)	Request body exceeded settings.DATA_UPLOAD_MAX_MEMORY_SIZE.
Traceback (most recent call last):
  File "/home/app_admin/venv_travelog/lib64/python3.9/site-packages/django/core/handlers/exception.py", line 56, in inner
    response = get_response(request)
  File "/home/app_admin/venv_travelog/lib64/python3.9/site-packages/django/core/handlers/base.py", line 185, in _get_response
    response = middleware_method(
  File "/home/app_admin/venv_travelog/lib64/python3.9/site-packages/django/middleware/csrf.py", line 471, in process_view
    self._check_token(request)
  File "/home/app_admin/venv_travelog/lib64/python3.9/site-packages/django/middleware/csrf.py", line 374, in _check_token
    request_csrf_token = request.POST.get("csrfmiddlewaretoken", "")
  File "/home/app_admin/venv_travelog/lib64/python3.9/site-packages/django/core/handlers/wsgi.py", line 100, in _get_post
    self._load_post_and_files()
  File "/home/app_admin/venv_travelog/lib64/python3.9/site-packages/django/http/request.py", line 373, in _load_post_and_files
    self._post, self._files = self.parse_file_upload(self.META, data)
  File "/home/app_admin/venv_travelog/lib64/python3.9/site-packages/django/http/request.py", line 323, in parse_file_upload
    return parser.parse()
  File "/home/app_admin/venv_travelog/lib64/python3.9/site-packages/django/http/multipartparser.py", line 123, in parse
    return self._parse()
  File "/home/app_admin/venv_travelog/lib64/python3.9/site-packages/django/http/multipartparser.py", line 245, in _parse
    raise RequestDataTooBig(
django.core.exceptions.RequestDataTooBig: Request body exceeded settings.DATA_UPLOAD_MAX_MEMORY_SIZE.
2024-05-29 16:56:47,934	[WARNING]	/home/app_admin/venv_travelog/lib64/python3.9/site-packages/django/utils/log.py(Line:241)	Bad Request: /profile_edit/15
2024-05-29 16:56:49,033	[WARNING]	/home/app_admin/venv_travelog/lib64/python3.9/site-packages/django/utils/log.py(Line:241)	Not Found: /favicon.ico
2024-05-29 17:06:36,905	[ERROR]	/home/app_admin/venv_travelog/lib64/python3.9/site-packages/django/core/handlers/exception.py(Line:125)	Invalid HTTP_HOST header: '34.230.218.223:443'. You may need to add '34.230.218.223' to ALLOWED_HOSTS.
Traceback (most recent call last):
  File "/home/app_admin/venv_travelog/lib64/python3.9/site-packages/django/core/handlers/exception.py", line 56, in inner
    response = get_response(request)
  File "/home/app_admin/venv_travelog/lib64/python3.9/site-packages/django/utils/deprecation.py", line 135, in __call__
    response = self.process_request(request)
  File "/home/app_admin/venv_travelog/lib64/python3.9/site-packages/django/middleware/common.py", line 48, in process_request
    host = request.get_host()
  File "/home/app_admin/venv_travelog/lib64/python3.9/site-packages/django/http/request.py", line 152, in get_host
    raise DisallowedHost(msg)
django.core.exceptions.DisallowedHost: Invalid HTTP_HOST header: '34.230.218.223:443'. You may need to add '34.230.218.223' to ALLOWED_HOSTS.
2024-05-29 17:06:36,915	[WARNING]	/home/app_admin/venv_travelog/lib64/python3.9/site-packages/django/utils/log.py(Line:241)	Bad Request: /dqgqoeCXckuwPtxov
2024-05-29 17:06:38,676	[ERROR]	/home/app_admin/venv_travelog/lib64/python3.9/site-packages/django/core/handlers/exception.py(Line:125)	Invalid HTTP_HOST header: '34.230.218.223:443'. You may need to add '34.230.218.223' to ALLOWED_HOSTS.
Traceback (most recent call last):
  File "/home/app_admin/venv_travelog/lib64/python3.9/site-packages/django/core/handlers/exception.py", line 56, in inner
    response = get_response(request)
  File "/home/app_admin/venv_travelog/lib64/python3.9/site-packages/django/utils/deprecation.py", line 135, in __call__
    response = self.process_request(request)
  File "/home/app_admin/venv_travelog/lib64/python3.9/site-packages/django/middleware/common.py", line 48, in process_request
    host = request.get_host()
  File "/home/app_admin/venv_travelog/lib64/python3.9/site-packages/django/http/request.py", line 152, in get_host
    raise DisallowedHost(msg)
django.core.exceptions.DisallowedHost: Invalid HTTP_HOST header: '34.230.218.223:443'. You may need to add '34.230.218.223' to ALLOWED_HOSTS.
2024-05-29 17:06:38,677	[WARNING]	/home/app_admin/venv_travelog/lib64/python3.9/site-packages/django/utils/log.py(Line:241)	Bad Request: /dqgqoeCXckuwPtxov
2024-05-29 17:41:55,176	[ERROR]	/home/app_admin/venv_travelog/lib64/python3.9/site-packages/django/utils/log.py(Line:241)	Internal Server Error: /home/
Traceback (most recent call last):
  File "/home/app_admin/venv_travelog/lib64/python3.9/site-packages/django/core/handlers/exception.py", line 56, in inner
    response = get_response(request)
  File "/home/app_admin/venv_travelog/lib64/python3.9/site-packages/django/core/handlers/base.py", line 197, in _get_response
    response = wrapped_callback(request, *callback_args, **callback_kwargs)
  File "/home/app_admin/venv_travelog/lib64/python3.9/site-packages/django/views/generic/base.py", line 103, in view
    return self.dispatch(request, *args, **kwargs)
  File "/home/app_admin/venv_travelog/lib64/python3.9/site-packages/django/views/generic/base.py", line 142, in dispatch
    return handler(request, *args, **kwargs)
  File "/home/app_admin/venv_travelog/lib64/python3.9/site-packages/django/views/generic/list.py", line 154, in get
    self.object_list = self.get_queryset()
  File "/home/app_admin/venv_travelog/travelog/travelog_app/views.py", line 57, in get_queryset
    queryset = queryset.filter(Q(user_id__in = to_follow_users) | Q(user_id__in = user)).order_by('created_at')
  File "/home/app_admin/venv_travelog/lib64/python3.9/site-packages/django/db/models/query.py", line 1421, in filter
    return self._filter_or_exclude(False, args, kwargs)
  File "/home/app_admin/venv_travelog/lib64/python3.9/site-packages/django/db/models/query.py", line 1439, in _filter_or_exclude
    clone._filter_or_exclude_inplace(negate, args, kwargs)
  File "/home/app_admin/venv_travelog/lib64/python3.9/site-packages/django/db/models/query.py", line 1446, in _filter_or_exclude_inplace
    self._query.add_q(Q(*args, **kwargs))
  File "/home/app_admin/venv_travelog/lib64/python3.9/site-packages/django/db/models/sql/query.py", line 1532, in add_q
    clause, _ = self._add_q(q_object, self.used_aliases)
  File "/home/app_admin/venv_travelog/lib64/python3.9/site-packages/django/db/models/sql/query.py", line 1562, in _add_q
    child_clause, needed_inner = self.build_filter(
  File "/home/app_admin/venv_travelog/lib64/python3.9/site-packages/django/db/models/sql/query.py", line 1388, in build_filter
    return self._add_q(
  File "/home/app_admin/venv_travelog/lib64/python3.9/site-packages/django/db/models/sql/query.py", line 1562, in _add_q
    child_clause, needed_inner = self.build_filter(
  File "/home/app_admin/venv_travelog/lib64/python3.9/site-packages/django/db/models/sql/query.py", line 1478, in build_filter
    condition = self.build_lookup(lookups, col, value)
  File "/home/app_admin/venv_travelog/lib64/python3.9/site-packages/django/db/models/sql/query.py", line 1303, in build_lookup
    lookup = lookup_class(lhs, rhs)
  File "/home/app_admin/venv_travelog/lib64/python3.9/site-packages/django/db/models/lookups.py", line 27, in __init__
    self.rhs = self.get_prep_lookup()
  File "/home/app_admin/venv_travelog/lib64/python3.9/site-packages/django/db/models/fields/related_lookups.py", line 79, in get_prep_lookup
    self.rhs = [get_normalized_value(val, self.lhs)[0] for val in self.rhs]
  File "/home/app_admin/venv_travelog/lib64/python3.9/site-packages/django/utils/functional.py", line 268, in inner
    return func(_wrapped, *args)
TypeError: 'CustomUser' object is not iterable
2024-05-29 17:41:55,518	[WARNING]	/home/app_admin/venv_travelog/lib64/python3.9/site-packages/django/utils/log.py(Line:241)	Not Found: /favicon.ico
