2024-06-04 23:34:48,929	[ERROR]	/home/app_admin/venv_travelog/lib64/python3.9/site-packages/django/core/handlers/exception.py(Line:125)	Invalid HTTP_HOST header: '34.230.218.223'. You may need to add '34.230.218.223' to ALLOWED_HOSTS.
Traceback (most recent call last):
  File "/home/app_admin/venv_travelog/lib64/python3.9/site-packages/django/core/handlers/exception.py", line 56, in inner
    response = get_response(request)
  File "/home/app_admin/venv_travelog/lib64/python3.9/site-packages/django/utils/deprecation.py", line 135, in __call__
    response = self.process_request(request)
  File "/home/app_admin/venv_travelog/lib64/python3.9/site-packages/django/middleware/common.py", line 48, in process_request
    host = request.get_host()
  File "/home/app_admin/venv_travelog/lib64/python3.9/site-packages/django/http/request.py", line 152, in get_host
    raise DisallowedHost(msg)
django.core.exceptions.DisallowedHost: Invalid HTTP_HOST header: '34.230.218.223'. You may need to add '34.230.218.223' to ALLOWED_HOSTS.
2024-06-04 23:34:49,132	[WARNING]	/home/app_admin/venv_travelog/lib64/python3.9/site-packages/django/utils/log.py(Line:241)	Bad Request: /
2024-06-04 23:34:49,721	[ERROR]	/home/app_admin/venv_travelog/lib64/python3.9/site-packages/django/core/handlers/exception.py(Line:125)	Invalid HTTP_HOST header: '34.230.218.223'. You may need to add '34.230.218.223' to ALLOWED_HOSTS.
Traceback (most recent call last):
  File "/home/app_admin/venv_travelog/lib64/python3.9/site-packages/django/core/handlers/exception.py", line 56, in inner
    response = get_response(request)
  File "/home/app_admin/venv_travelog/lib64/python3.9/site-packages/django/utils/deprecation.py", line 135, in __call__
    response = self.process_request(request)
  File "/home/app_admin/venv_travelog/lib64/python3.9/site-packages/django/middleware/common.py", line 48, in process_request
    host = request.get_host()
  File "/home/app_admin/venv_travelog/lib64/python3.9/site-packages/django/http/request.py", line 152, in get_host
    raise DisallowedHost(msg)
django.core.exceptions.DisallowedHost: Invalid HTTP_HOST header: '34.230.218.223'. You may need to add '34.230.218.223' to ALLOWED_HOSTS.
2024-06-04 23:34:49,722	[WARNING]	/home/app_admin/venv_travelog/lib64/python3.9/site-packages/django/utils/log.py(Line:241)	Bad Request: /
2024-06-04 23:34:50,471	[ERROR]	/home/app_admin/venv_travelog/lib64/python3.9/site-packages/django/core/handlers/exception.py(Line:125)	Invalid HTTP_HOST header: '34.230.218.223'. You may need to add '34.230.218.223' to ALLOWED_HOSTS.
Traceback (most recent call last):
  File "/home/app_admin/venv_travelog/lib64/python3.9/site-packages/django/core/handlers/exception.py", line 56, in inner
    response = get_response(request)
  File "/home/app_admin/venv_travelog/lib64/python3.9/site-packages/django/utils/deprecation.py", line 135, in __call__
    response = self.process_request(request)
  File "/home/app_admin/venv_travelog/lib64/python3.9/site-packages/django/middleware/common.py", line 48, in process_request
    host = request.get_host()
  File "/home/app_admin/venv_travelog/lib64/python3.9/site-packages/django/http/request.py", line 152, in get_host
    raise DisallowedHost(msg)
django.core.exceptions.DisallowedHost: Invalid HTTP_HOST header: '34.230.218.223'. You may need to add '34.230.218.223' to ALLOWED_HOSTS.
2024-06-04 23:34:50,471	[WARNING]	/home/app_admin/venv_travelog/lib64/python3.9/site-packages/django/utils/log.py(Line:241)	Bad Request: /
2024-06-04 23:34:50,698	[ERROR]	/home/app_admin/venv_travelog/lib64/python3.9/site-packages/django/core/handlers/exception.py(Line:125)	Invalid HTTP_HOST header: '34.230.218.223'. You may need to add '34.230.218.223' to ALLOWED_HOSTS.
Traceback (most recent call last):
  File "/home/app_admin/venv_travelog/lib64/python3.9/site-packages/django/core/handlers/exception.py", line 56, in inner
    response = get_response(request)
  File "/home/app_admin/venv_travelog/lib64/python3.9/site-packages/django/utils/deprecation.py", line 135, in __call__
    response = self.process_request(request)
  File "/home/app_admin/venv_travelog/lib64/python3.9/site-packages/django/middleware/common.py", line 48, in process_request
    host = request.get_host()
  File "/home/app_admin/venv_travelog/lib64/python3.9/site-packages/django/http/request.py", line 152, in get_host
    raise DisallowedHost(msg)
django.core.exceptions.DisallowedHost: Invalid HTTP_HOST header: '34.230.218.223'. You may need to add '34.230.218.223' to ALLOWED_HOSTS.
2024-06-04 23:34:50,699	[WARNING]	/home/app_admin/venv_travelog/lib64/python3.9/site-packages/django/utils/log.py(Line:241)	Bad Request: /favicon.ico
2024-06-05 00:44:29,901	[ERROR]	/home/app_admin/venv_travelog/lib64/python3.9/site-packages/django/core/handlers/exception.py(Line:125)	Invalid HTTP_HOST header: '34.230.218.223'. You may need to add '34.230.218.223' to ALLOWED_HOSTS.
Traceback (most recent call last):
  File "/home/app_admin/venv_travelog/lib64/python3.9/site-packages/django/core/handlers/exception.py", line 56, in inner
    response = get_response(request)
  File "/home/app_admin/venv_travelog/lib64/python3.9/site-packages/django/utils/deprecation.py", line 135, in __call__
    response = self.process_request(request)
  File "/home/app_admin/venv_travelog/lib64/python3.9/site-packages/django/middleware/common.py", line 48, in process_request
    host = request.get_host()
  File "/home/app_admin/venv_travelog/lib64/python3.9/site-packages/django/http/request.py", line 152, in get_host
    raise DisallowedHost(msg)
django.core.exceptions.DisallowedHost: Invalid HTTP_HOST header: '34.230.218.223'. You may need to add '34.230.218.223' to ALLOWED_HOSTS.
2024-06-05 00:44:30,091	[WARNING]	/home/app_admin/venv_travelog/lib64/python3.9/site-packages/django/utils/log.py(Line:241)	Bad Request: /
